Workbook

Sheet Calculator
A1: 📡 Long Wire Antenna + UnUn — Multi-Band Optimizer
A2: By Emiliano Gonzalez LU3VEA – lu3vea@gmail.com – License: CC0 v1.0 | v1.1
A4: Select YES/NO for each band · Adjust Velocity Factor · See 'Length Sweep' sheet for color-coded results · All dimensions in METERS
A6: ⚙ PARAMETERS — Blue cells are editable inputs
A7: Velocity Factor (VF): | D7: 0.95 | E7: ← Editable. Recommended default: 0.95 (insulated wire + end-effec). Bare copper in free air: 0.975–0.98. Insulated (PVC/poly): 0.92–0.96.
A9: 📻 BAND SELECTION — Change 'ACTIVE' column to YES or NO (dropdown available)
A10: ⚠ Lengths at an INTEGER multiple of λ/2 (very high feedpoint Z) OR at λ/4 multiples (very low feedpoint Z) cause poor UnUn matching — the algorithm AVOIDS both. Wires shorter than λ/4 of the lowest active band are also penalised (scored 0).
A11: Band | B11: f Low (MHz) | C11: f High (MHz) | D11: f Center (MHz) | E11: ACTIVE | F11: λ/2 (meters) | G11: λ/4 (meters) | H11: Min Wire (meters)
A12: 160m | B12: 1.8 | C12: 2 | D12: =(B12+C12)/2 -> 1.9 | E12: NO | F12: =$D$7*150/D12 -> 75 | G12: =F12/2 -> 37.5 | H12: =$D$7*75/D12 -> 37.5 | K12: {=IFERROR(INDEX($A$12:$A$22,SMALL(IF($E$12:$E$22="YES",ROW($A$12:$A$22)-ROW($A$12)+1),1),1),"")} -> 40m
A13: 80m | B13: 3.5 | C13: 3.8 | D13: =(B13+C13)/2 -> 3.65 | E13: NO | F13: =$D$7*150/D13 -> 39.041096 | G13: =F13/2 -> 19.520548 | H13: =$D$7*75/D13 -> 19.520548 | K13: {=IFERROR(INDEX($A$12:$A$22,SMALL(IF($E$12:$E$22="YES",ROW($A$12:$A$22)-ROW($A$12)+1),2),1),"")} -> 20m
A14: 60m | B14: 5.3515 | C14: 5.3665 | D14: =(B14+C14)/2 -> 5.359 | E14: NO | F14: =$D$7*150/D14 -> 26.590782 | G14: =F14/2 -> 13.295391 | H14: =$D$7*75/D14 -> 13.295391 | K14: {=IFERROR(INDEX($A$12:$A$22,SMALL(IF($E$12:$E$22="YES",ROW($A$12:$A$22)-ROW($A$12)+1),3),1),"")}
A15: 40m | B15: 7 | C15: 7.3 | D15: =(B15+C15)/2 -> 7.15 | E15: YES | F15: =$D$7*150/D15 -> 19.93007 | G15: =F15/2 -> 9.965035 | H15: =$D$7*75/D15 -> 9.965035 | K15: {=IFERROR(INDEX($A$12:$A$22,SMALL(IF($E$12:$E$22="YES",ROW($A$12:$A$22)-ROW($A$12)+1),4),1),"")}
A16: 30m | B16: 10.1 | C16: 10.15 | D16: =(B16+C16)/2 -> 10.125 | E16: NO | F16: =$D$7*150/D16 -> 14.074074 | G16: =F16/2 -> 7.037037 | H16: =$D$7*75/D16 -> 7.037037 | K16: {=IFERROR(INDEX($A$12:$A$22,SMALL(IF($E$12:$E$22="YES",ROW($A$12:$A$22)-ROW($A$12)+1),5),1),"")}
A17: 20m | B17: 14 | C17: 14.35 | D17: =(B17+C17)/2 -> 14.175 | E17: YES | F17: =$D$7*150/D17 -> 10.05291 | G17: =F17/2 -> 5.026455 | H17: =$D$7*75/D17 -> 5.026455 | K17: {=IFERROR(INDEX($A$12:$A$22,SMALL(IF($E$12:$E$22="YES",ROW($A$12:$A$22)-ROW($A$12)+1),6),1),"")}
A18: 17m | B18: 18.068 | C18: 18.168 | D18: =(B18+C18)/2 -> 18.118 | E18: NO | F18: =$D$7*150/D18 -> 7.8651065 | G18: =F18/2 -> 3.9325533 | H18: =$D$7*75/D18 -> 3.9325533 | K18: {=IFERROR(INDEX($A$12:$A$22,SMALL(IF($E$12:$E$22="YES",ROW($A$12:$A$22)-ROW($A$12)+1),7),1),"")}
A19: 15m | B19: 21 | C19: 21.45 | D19: =(B19+C19)/2 -> 21.225 | E19: NO | F19: =$D$7*150/D19 -> 6.7137809 | G19: =F19/2 -> 3.3568905 | H19: =$D$7*75/D19 -> 3.3568905 | K19: {=IFERROR(INDEX($A$12:$A$22,SMALL(IF($E$12:$E$22="YES",ROW($A$12:$A$22)-ROW($A$12)+1),8),1),"")}
A20: 12m | B20: 24.89 | C20: 24.99 | D20: =(B20+C20)/2 -> 24.94 | E20: NO | F20: =$D$7*150/D20 -> 5.7137129 | G20: =F20/2 -> 2.8568565 | H20: =$D$7*75/D20 -> 2.8568565 | K20: {=IFERROR(INDEX($A$12:$A$22,SMALL(IF($E$12:$E$22="YES",ROW($A$12:$A$22)-ROW($A$12)+1),9),1),"")}
A21: 10m | B21: 28 | C21: 29.7 | D21: =(B21+C21)/2 -> 28.85 | E21: NO | F21: =$D$7*150/D21 -> 4.9393414 | G21: =F21/2 -> 2.4696707 | H21: =$D$7*75/D21 -> 2.4696707 | K21: {=IFERROR(INDEX($A$12:$A$22,SMALL(IF($E$12:$E$22="YES",ROW($A$12:$A$22)-ROW($A$12)+1),10),1),"")}
A22: 6m | B22: 50 | C22: 54 | D22: =(B22+C22)/2 -> 52 | E22: NO | F22: =$D$7*150/D22 -> 2.7403846 | G22: =F22/2 -> 1.3701923 | H22: =$D$7*75/D22 -> 1.3701923 | K22: {=IFERROR(INDEX($A$12:$A$22,SMALL(IF($E$12:$E$22="YES",ROW($A$12:$A$22)-ROW($A$12)+1),11),1),"")}
A24: 🔌 COUNTERPOISE (Ground Reference Wire)
A25: Recommended counterpoise (m): | D25: =IF(COUNTIF(E12:E22,"YES")=0,"N/A",SUMPRODUCT(MAX((E12:E22="YES")*H12:H22))) -> 9.965035 | E25: λ/4 of lowest active band. Multiple radials also effective. Keep counterpoise straigh.
A27: 🏆 TOP 10 RECOMMENDED WIRE LENGTHS (computed from 'Length Sweep' sheet — updates with band selection)
A28: Rank | B28: Wire Length (meters) | C28: Wire Length (cm) | D28: Avoidance Score | E28: Quality Rating | F28: λ/2 check (lowest active band; ok = not integer and not n+0.5) | G28: Practical Notes | H28: Optimal UnUn (no CP / w/CP)
A29: # 1 | B29: =IFERROR(INDEX('Length Sweep'!$A$7:$A$557,MATCH(1,'Length Sweep'!$N$7:$N$557,0)),"-") -> 13.3 | C29: =IFERROR(B29*100,"-") -> 1330 | D29: =IFERROR(LARGE('Length Sweep'!$M$7:$M$557,1),"-") -> 0.15333333 | E29: =IF(ISNUMBER(D29),IF(D29>=0.13,"★★★ EXCELLENT",IF(D29>=0.12,"★★ GOOD",IF(D29>=0.07,"★ FAIR",IF(D29>=0.025,"⚠ MARGINAL","✗ AVOID")))),"—") -> ★★★ EXCELLENT | F29: =IFERROR(TEXT(B29/SUMPRODUCT(MAX((Calculator!$E$12:$E$22="YES")*Calculator!$F$12:$F$22)),"0.00")&" × λ/2 @lowest band","—") -> 0.67 × λ/2 @lowest band | G29: =IF(ISNUMBER(B29),IF(B29<10,"Short – portable use only",IF(B29<18,"Portable / SOTA",IF(B29<30,"Good portable/home",IF(B29<45,"Excellent home station","Long wire – max performance")))),"-") -> Portable / SOTA | H29: =IFERROR("No CP: "&'UnUn Ratio Optimizer'!D107&" (avg "&TEXT('UnUn Ratio Optimizer'!E107,"0.00")&")"&CHAR(10)&"w/CP: "&'UnUn Ratio Optimizer'!I107&" (avg "&TEXT('UnUn Ratio Optimizer'!J107,"0.00")&")","—") -> No CP: 27:1 (avg 16.64) w/CP: 27:1 (avg 13.68)
A30: # 2 | B30: =IFERROR(INDEX('Length Sweep'!$A$7:$A$557,MATCH(2,'Length Sweep'!$N$7:$N$557,0)),"-") -> 13.4 | C30: =IFERROR(B30*100,"-") -> 1340 | D30: =IFERROR(LARGE('Length Sweep'!$M$7:$M$557,2),"-") -> 0.15059649 | E30: =IF(ISNUMBER(D30),IF(D30>=0.13,"★★★ EXCELLENT",IF(D30>=0.12,"★★ GOOD",IF(D30>=0.07,"★ FAIR",IF(D30>=0.025,"⚠ MARGINAL","✗ AVOID")))),"—") -> ★★★ EXCELLENT | F30: =IFERROR(TEXT(B30/SUMPRODUCT(MAX((Calculator!$E$12:$E$22="YES")*Calculator!$F$12:$F$22)),"0.00")&" × λ/2 @lowest band","—") -> 0.67 × λ/2 @lowest band | G30: =IF(ISNUMBER(B30),IF(B30<10,"Short – portable use only",IF(B30<18,"Portable / SOTA",IF(B30<30,"Good portable/home",IF(B30<45,"Excellent home station","Long wire – max performance")))),"-") -> Portable / SOTA | H30: =IFERROR("No CP: "&'UnUn Ratio Optimizer'!D108&" (avg "&TEXT('UnUn Ratio Optimizer'!E108,"0.00")&")"&CHAR(10)&"w/CP: "&'UnUn Ratio Optimizer'!I108&" (avg "&TEXT('UnUn Ratio Optimizer'!J108,"0.00")&")","—") -> No CP: 26:1 (avg 17.00) w/CP: 27:1 (avg 13.95)
A31: # 3 | B31: =IFERROR(INDEX('Length Sweep'!$A$7:$A$557,MATCH(3,'Length Sweep'!$N$7:$N$557,0)),"-") -> 13.2 | C31: =IFERROR(B31*100,"-") -> 1320 | D31: =IFERROR(LARGE('Length Sweep'!$M$7:$M$557,3),"-") -> 0.14842105 | E31: =IF(ISNUMBER(D31),IF(D31>=0.13,"★★★ EXCELLENT",IF(D31>=0.12,"★★ GOOD",IF(D31>=0.07,"★ FAIR",IF(D31>=0.025,"⚠ MARGINAL","✗ AVOID")))),"—") -> ★★★ EXCELLENT | F31: =IFERROR(TEXT(B31/SUMPRODUCT(MAX((Calculator!$E$12:$E$22="YES")*Calculator!$F$12:$F$22)),"0.00")&" × λ/2 @lowest band","—") -> 0.66 × λ/2 @lowest band | G31: =IF(ISNUMBER(B31),IF(B31<10,"Short – portable use only",IF(B31<18,"Portable / SOTA",IF(B31<30,"Good portable/home",IF(B31<45,"Excellent home station","Long wire – max performance")))),"-") -> Portable / SOTA | H31: =IFERROR("No CP: "&'UnUn Ratio Optimizer'!D109&" (avg "&TEXT('UnUn Ratio Optimizer'!E109,"0.00")&")"&CHAR(10)&"w/CP: "&'UnUn Ratio Optimizer'!I109&" (avg "&TEXT('UnUn Ratio Optimizer'!J109,"0.00")&")","—") -> No CP: 27:1 (avg 16.28) w/CP: 27:1 (avg 13.38)
A32: # 4 | B32: =IFERROR(INDEX('Length Sweep'!$A$7:$A$557,MATCH(4,'Length Sweep'!$N$7:$N$557,0)),"-") -> 23.3 | C32: =IFERROR(B32*100,"-") -> 2330 | D32: =IFERROR(LARGE('Length Sweep'!$M$7:$M$557,4),"-") -> 0.1445614 | E32: =IF(ISNUMBER(D32),IF(D32>=0.13,"★★★ EXCELLENT",IF(D32>=0.12,"★★ GOOD",IF(D32>=0.07,"★ FAIR",IF(D32>=0.025,"⚠ MARGINAL","✗ AVOID")))),"—") -> ★★★ EXCELLENT | F32: =IFERROR(TEXT(B32/SUMPRODUCT(MAX((Calculator!$E$12:$E$22="YES")*Calculator!$F$12:$F$22)),"0.00")&" × λ/2 @lowest band","—") -> 1.17 × λ/2 @lowest band | G32: =IF(ISNUMBER(B32),IF(B32<10,"Short – portable use only",IF(B32<18,"Portable / SOTA",IF(B32<30,"Good portable/home",IF(B32<45,"Excellent home station","Long wire – max performance")))),"-") -> Good portable/home | H32: =IFERROR("No CP: "&'UnUn Ratio Optimizer'!D110&" (avg "&TEXT('UnUn Ratio Optimizer'!E110,"0.00")&")"&CHAR(10)&"w/CP: "&'UnUn Ratio Optimizer'!I110&" (avg "&TEXT('UnUn Ratio Optimizer'!J110,"0.00")&")","—") -> No CP: 29:1 (avg 8.86) w/CP: 29:1 (avg 7.77)
A33: # 5 | B33: =IFERROR(INDEX('Length Sweep'!$A$7:$A$557,MATCH(5,'Length Sweep'!$N$7:$N$557,0)),"-") -> 23.4 | C33: =IFERROR(B33*100,"-") -> 2340 | D33: =IFERROR(LARGE('Length Sweep'!$M$7:$M$557,5),"-") -> 0.14357895 | E33: =IF(ISNUMBER(D33),IF(D33>=0.13,"★★★ EXCELLENT",IF(D33>=0.12,"★★ GOOD",IF(D33>=0.07,"★ FAIR",IF(D33>=0.025,"⚠ MARGINAL","✗ AVOID")))),"—") -> ★★★ EXCELLENT | F33: =IFERROR(TEXT(B33/SUMPRODUCT(MAX((Calculator!$E$12:$E$22="YES")*Calculator!$F$12:$F$22)),"0.00")&" × λ/2 @lowest band","—") -> 1.17 × λ/2 @lowest band | G33: =IF(ISNUMBER(B33),IF(B33<10,"Short – portable use only",IF(B33<18,"Portable / SOTA",IF(B33<30,"Good portable/home",IF(B33<45,"Excellent home station","Long wire – max performance")))),"-") -> Good portable/home | H33: =IFERROR("No CP: "&'UnUn Ratio Optimizer'!D111&" (avg "&TEXT('UnUn Ratio Optimizer'!E111,"0.00")&")"&CHAR(10)&"w/CP: "&'UnUn Ratio Optimizer'!I111&" (avg "&TEXT('UnUn Ratio Optimizer'!J111,"0.00")&")","—") -> No CP: 28:1 (avg 9.66) w/CP: 28:1 (avg 8.34)
A34: # 6 | B34: =IFERROR(INDEX('Length Sweep'!$A$7:$A$557,MATCH(6,'Length Sweep'!$N$7:$N$557,0)),"-") -> 13.1 | C34: =IFERROR(B34*100,"-") -> 1310 | D34: =IFERROR(LARGE('Length Sweep'!$M$7:$M$557,6),"-") -> 0.14350877 | E34: =IF(ISNUMBER(D34),IF(D34>=0.13,"★★★ EXCELLENT",IF(D34>=0.12,"★★ GOOD",IF(D34>=0.07,"★ FAIR",IF(D34>=0.025,"⚠ MARGINAL","✗ AVOID")))),"—") -> ★★★ EXCELLENT | F34: =IFERROR(TEXT(B34/SUMPRODUCT(MAX((Calculator!$E$12:$E$22="YES")*Calculator!$F$12:$F$22)),"0.00")&" × λ/2 @lowest band","—") -> 0.66 × λ/2 @lowest band | G34: =IF(ISNUMBER(B34),IF(B34<10,"Short – portable use only",IF(B34<18,"Portable / SOTA",IF(B34<30,"Good portable/home",IF(B34<45,"Excellent home station","Long wire – max performance")))),"—") -> Portable / SOTA | H34: =IFERROR("No CP: "&'UnUn Ratio Optimizer'!D112&" (avg "&TEXT('UnUn Ratio Optimizer'!E112,"0.00")&")"&CHAR(10)&"w/CP: "&'UnUn Ratio Optimizer'!I112&" (avg "&TEXT('UnUn Ratio Optimizer'!J112,"0.00")&")","—") -> No CP: 26:1 (avg 15.95) w/CP: 27:1 (avg 13.06)
A35: # 7 | B35: =IFERROR(INDEX('Length Sweep'!$A$7:$A$557,MATCH(7,'Length Sweep'!$N$7:$N$557,0)),"-") -> 16.7 | C35: =IFERROR(B35*100,"-") -> 1670 | D35: =IFERROR(LARGE('Length Sweep'!$M$7:$M$557,7),"-") -> 0.14070175 | E35: =IF(ISNUMBER(D35),IF(D35>=0.13,"★★★ EXCELLENT",IF(D35>=0.12,"★★ GOOD",IF(D35>=0.07,"★ FAIR",IF(D35>=0.025,"⚠ MARGINAL","✗ AVOID")))),"—") -> ★★★ EXCELLENT | F35: =IFERROR(TEXT(B35/SUMPRODUCT(MAX((Calculator!$E$12:$E$22="YES")*Calculator!$F$12:$F$22)),"0.00")&" × λ/2 @lowest band","—") -> 0.84 × λ/2 @lowest band | G35: =IF(ISNUMBER(B35),IF(B35<10,"Short – portable use only",IF(B35<18,"Portable / SOTA",IF(B35<30,"Good portable/home",IF(B35<45,"Excellent home station","Long wire – max performance")))),"—") -> Portable / SOTA | H35: =IFERROR("No CP: "&'UnUn Ratio Optimizer'!D113&" (avg "&TEXT('UnUn Ratio Optimizer'!E113,"0.00")&")"&CHAR(10)&"w/CP: "&'UnUn Ratio Optimizer'!I113&" (avg "&TEXT('UnUn Ratio Optimizer'!J113,"0.00")&")","—") -> No CP: 27:1 (avg 10.34) w/CP: 28:1 (avg 8.73)
A36: # 8 | B36: =IFERROR(INDEX('Length Sweep'!$A$7:$A$557,MATCH(8,'Length Sweep'!$N$7:$N$557,0)),"-") -> 13.5 | C36: =IFERROR(B36*100,"-") -> 1350 | D36: =IFERROR(LARGE('Length Sweep'!$M$7:$M$557,8),"-") -> 0.14052632 | E36: =IF(ISNUMBER(D36),IF(D36>=0.13,"★★★ EXCELLENT",IF(D36>=0.12,"★★ GOOD",IF(D36>=0.07,"★ FAIR",IF(D36>=0.025,"⚠ MARGINAL","✗ AVOID")))),"—") -> ★★★ EXCELLENT | F36: =IFERROR(TEXT(B36/SUMPRODUCT(MAX((Calculator!$E$12:$E$22="YES")*Calculator!$F$12:$F$22)),"0.00")&" × λ/2 @lowest band","—") -> 0.68 × λ/2 @lowest band | G36: =IF(ISNUMBER(B36),IF(B36<10,"Short – portable use only",IF(B36<18,"Portable / SOTA",IF(B36<30,"Good portable/home",IF(B36<45,"Excellent home station","Long wire – max performance")))),"—") -> Portable / SOTA | H36: =IFERROR("No CP: "&'UnUn Ratio Optimizer'!D114&" (avg "&TEXT('UnUn Ratio Optimizer'!E114,"0.00")&")"&CHAR(10)&"w/CP: "&'UnUn Ratio Optimizer'!I114&" (avg "&TEXT('UnUn Ratio Optimizer'!J114,"0.00")&")","—") -> No CP: 26:1 (avg 17.34) w/CP: 26:1 (avg 14.16)
A37: # 9 | B37: =IFERROR(INDEX('Length Sweep'!$A$7:$A$557,MATCH(9,'Length Sweep'!$N$7:$N$557,0)),"-") -> 23.2 | C37: =IFERROR(B37*100,"-") -> 2320 | D37: =IFERROR(LARGE('Length Sweep'!$M$7:$M$557,9),"-") -> 0.13964912 | E37: =IF(ISNUMBER(D37),IF(D37>=0.13,"★★★ EXCELLENT",IF(D37>=0.12,"★★ GOOD",IF(D37>=0.07,"★ FAIR",IF(D37>=0.025,"⚠ MARGINAL","✗ AVOID")))),"—") -> ★★★ EXCELLENT | F37: =IFERROR(TEXT(B37/SUMPRODUCT(MAX((Calculator!$E$12:$E$22="YES")*Calculator!$F$12:$F$22)),"0.00")&" × λ/2 @lowest band","—") -> 1.16 × λ/2 @lowest band | G37: =IF(ISNUMBER(B37),IF(B37<10,"Short – portable use only",IF(B37<18,"Portable / SOTA",IF(B37<30,"Good portable/home",IF(B37<45,"Excellent home station","Long wire – max performance")))),"—") -> Good portable/home | H37: =IFERROR("No CP: "&'UnUn Ratio Optimizer'!D115&" (avg "&TEXT('UnUn Ratio Optimizer'!E115,"0.00")&")"&CHAR(10)&"w/CP: "&'UnUn Ratio Optimizer'!I115&" (avg "&TEXT('UnUn Ratio Optimizer'!J115,"0.00")&")","—") -> No CP: 30:1 (avg 8.07) w/CP: 31:1 (avg 7.19)
A38: # 10 | B38: =IFERROR(INDEX('Length Sweep'!$A$7:$A$557,MATCH(10,'Length Sweep'!$N$7:$N$557,0)),"-") -> 16.8 | C38: =IFERROR(B38*100,"-") -> 1680 | D38: =IFERROR(LARGE('Length Sweep'!$M$7:$M$557,10),"-") -> 0.13936842 | E38: =IF(ISNUMBER(D38),IF(D38>=0.13,"★★★ EXCELLENT",IF(D38>=0.12,"★★ GOOD",IF(D38>=0.07,"★ FAIR",IF(D38>=0.025,"⚠ MARGINAL","✗ AVOID")))),"—") -> ★★★ EXCELLENT | F38: =IFERROR(TEXT(B38/SUMPRODUCT(MAX((Calculator!$E$12:$E$22="YES")*Calculator!$F$12:$F$22)),"0.00")&" × λ/2 @lowest band","—") -> 0.84 × λ/2 @lowest band | G38: =IF(ISNUMBER(B38),IF(B38<10,"Short – portable use only",IF(B38<18,"Portable / SOTA",IF(B38<30,"Good portable/home",IF(B38<45,"Excellent home station","Long wire – max performance")))),"—") -> Portable / SOTA | H38: =IFERROR("No CP: "&'UnUn Ratio Optimizer'!D116&" (avg "&TEXT('UnUn Ratio Optimizer'!E116,"0.00")&")"&CHAR(10)&"w/CP: "&'UnUn Ratio Optimizer'!I116&" (avg "&TEXT('UnUn Ratio Optimizer'!J116,"0.00")&")","—") -> No CP: 28:1 (avg 9.57) w/CP: 29:1 (avg 8.22)
A39: ℹ Avoidance Score explanation: 0.25 = wire is at maximum distance from ALL resonances (ideal: 3λ/8 or 5λ/8); 0.00 = wire IS resonant (half-wave or quarter-wave, extremely high or low impedance, avoid); Score ≥ 0.20 = excellent; Score ≥ 0.12 = good practice.
A41: 🔁 CHOKE / BALUN INSTALLATION GUIDANCE
A42: Choke placement: | C42: Install current choke (CMC) at the feedpoint, between coax and UnUn primary, to suppress common-mode current on the coax shield.
A43: Choke impedance: | C43: Target ≥ 1000 Ω common-mode at lowest active band. FT-240-31 or FT-240-43, 10–12 turns bifilar coax, covers 1.8–30 MHz.
A44: Coax routing: | C44: Run coax perpendicular to antenna wire for ≥ 1–2 m after choke. Avoid coax lengths at λ/2 multiples of any active band.
A45: Tuner in-line: | C45: If using ATU: choke goes between ATU output and coax run, not between radio and ATU.
A46: Multi-band use: | C46: 2× FT-240-31 stacked with 12 turns bifilar gives good coverage 1.8–54 MHz with low insertion loss.
...

Sheet VSWR Calculator
A1: 📡 VSWR Estimator — Long Wire Antenna + Configurable UnUn Ratio
A2: By Emiliano Gonzalez LU3VEA – lu3vea@gmail.com – License: CC0 v1.0
A4: Wire Length (m): | C4: 43.4 | D4: ← Select wire length (m). Tip: use a Top-10 wire length from Calculator sheet for best results.
A5: UnUn Ratio (N:1): | C5: =IFERROR(VALUE(LEFT(INDEX('UnUn Ratio Optimizer'!$I$107:$I$116,MATCH(C4,'UnUn Ratio Optimizer'!$B$107:$B$116,0)),FIND(":",INDEX('UnUn Ratio Optimizer'!$I$107:$I$116,MATCH(C4,'UnUn Ratio Optimizer'!$B$107:$B$116,0)))-1)),9) -> 9
A7: Band | B7: Active | C7: λ/2 (m) | D7: λ/4 (m) | E7: L / λ½ (frac) | F7: Z_wire (Ω, est.) | G7: X_est (Ω, reactance) | H7: VSWR (complex Z)
A8: =Calculator!A12 -> 160m | B8: =Calculator!$E$12 -> NO | C8: =Calculator!$F$12 -> 75 | D8: =ROUND(Calculator!$G$12,2) -> 37.5 | E8: =IF(AND(B8="YES",$C$4>=D8),MOD($C$4/C8,1),"—") -> — | F8: =IF(AND(B8="YES",$C$4>=D8),ROUND(50*POWER(80,COS(PI()*MOD($C$4/C8,1))^2),0),"—") -> — | G8: =IF(B8<>"YES","—",IF($C$4<D8,"< λ/4",1500*SIN(2*PI()*MOD($C$4/C8,1)))) -> — | H8: =IF(B8<>"YES","—",IF($C$4<D8,"—",(1+SQRT((((F8)-$C$5*50)^2+(G8)^2)/(((F8)+$C$5*50)^2+(G8)^2)))/(1-SQRT((((F8)-$C$5*50)^2+(G8)^2)/(((F8)+$C$5*50)^2+(G8)^2))))) -> —
A9: =Calculator!A13 -> 80m | B9: =Calculator!$E$13 -> NO | C9: =Calculator!$F$13 -> 39.041096 | D9: =ROUND(Calculator!$G$13,2) -> 19.52 | E9: =IF(AND(B9="YES",$C$4>=D9),MOD($C$4/C9,1),"—") -> — | F9: =IF(AND(B9="YES",$C$4>=D9),ROUND(50*POWER(80,COS(PI()*MOD($C$4/C9,1))^2),0),"—") -> — | G9: =IF(B9<>"YES","—",IF($C$4<D9,"< λ/4",1500*SIN(2*PI()*MOD($C$4/C9,1)))) -> — | H9: =IF(B9<>"YES","—",IF($C$4<D9,"—",(1+SQRT((((F9)-$C$5*50)^2+(G9)^2)/(((F9)+$C$5*50)^2+(G9)^2)))/(1-SQRT((((F9)-$C$5*50)^2+(G9)^2)/(((F9)+$C$5*50)^2+(G9)^2))))) -> —
A10: =Calculator!A14 -> 60m | B10: =Calculator!$E$14 -> NO | C10: =Calculator!$F$14 -> 26.590782 | D10: =ROUND(Calculator!$G$14,2) -> 13.3 | E10: =IF(AND(B10="YES",$C$4>=D10),MOD($C$4/C10,1),"—") -> — | F10: =IF(AND(B10="YES",$C$4>=D10),ROUND(50*POWER(80,COS(PI()*MOD($C$4/C10,1))^2),0),"—") -> — | G10: =IF(B10<>"YES","—",IF($C$4<D10,"< λ/4",1500*SIN(2*PI()*MOD($C$4/C10,1)))) -> — | H10: =IF(B10<>"YES","—",IF($C$4<D10,"—",(1+SQRT((((F10)-$C$5*50)^2+(G10)^2)/(((F10)+$C$5*50)^2+(G10)^2)))/(1-SQRT((((F10)-$C$5*50)^2+(G10)^2)/(((F10)+$C$5*50)^2+(G10)^2))))) -> —
A11: =Calculator!A15 -> 40m | B11: =Calculator!$E$15 -> YES | C11: =Calculator!$F$15 -> 19.93007 | D11: =ROUND(Calculator!$G$15,2) -> 9.97 | E11: =IF(AND(B11="YES",$C$4>=D11),MOD($C$4/C11,1),"—") -> 0.17761404 | F11: =IF(AND(B11="YES",$C$4>=D11),ROUND(50*POWER(80,COS(PI()*MOD($C$4/C11,1))^2),0),"—") -> 1171 | G11: =IF(B11<>"YES","—",IF($C$4<D11,"< λ/4",1500*SIN(2*PI()*MOD($C$4/C11,1)))) -> 1347.5138 | H11: =IF(B11<>"YES","—",IF($C$4<D11,"—",(1+SQRT((((F11)-$C$5*50)^2+(G11)^2)/(((F11)+$C$5*50)^2+(G11)^2)))/(1-SQRT((((F11)-$C$5*50)^2+(G11)^2)/(((F11)+$C$5*50)^2+(G11)^2))))) -> 6.27295
A12: =Calculator!A16 -> 30m | B12: =Calculator!$E$16 -> NO | C12: =Calculator!$F$16 -> 14.074074 | D12: =ROUND(Calculator!$G$16,2) -> 7.04 | E12: =IF(AND(B12="YES",$C$4>=D12),MOD($C$4/C12,1),"—") -> — | F12: =IF(AND(B12="YES",$C$4>=D12),ROUND(50*POWER(80,COS(PI()*MOD($C$4/C12,1))^2),0),"—") -> — | G12: =IF(B12<>"YES","—",IF($C$4<D12,"< λ/4",1500*SIN(2*PI()*MOD($C$4/C12,1)))) -> — | H12: =IF(B12<>"YES","—",IF($C$4<D12,"—",(1+SQRT((((F12)-$C$5*50)^2+(G12)^2)/(((F12)+$C$5*50)^2+(G12)^2)))/(1-SQRT((((F12)-$C$5*50)^2+(G12)^2)/(((F12)+$C$5*50)^2+(G12)^2))))) -> —
A13: =Calculator!A17 -> 20m | B13: =Calculator!$E$17 -> YES | C13: =Calculator!$F$17 -> 10.05291 | D13: =ROUND(Calculator!$G$17,2) -> 5.03 | E13: =IF(AND(B13="YES",$C$4>=D13),MOD($C$4/C13,1),"—") -> 0.31715789 | F13: =IF(AND(B13="YES",$C$4>=D13),ROUND(50*POWER(80,COS(PI()*MOD($C$4/C13,1))^2),0),"—") -> 182 | G13: =IF(B13<>"YES","—",IF($C$4<D13,"< λ/4",1500*SIN(2*PI()*MOD($C$4/C13,1)))) -> 1368.4286 | H13: =IF(B13<>"YES","—",IF($C$4<D13,"—",(1+SQRT((((F13)-$C$5*50)^2+(G13)^2)/(((F13)+$C$5*50)^2+(G13)^2)))/(1-SQRT((((F13)-$C$5*50)^2+(G13)^2)/(((F13)+$C$5*50)^2+(G13)^2))))) -> 25.702495
A14: =Calculator!A18 -> 17m | B14: =Calculator!$E$18 -> NO | C14: =Calculator!$F$18 -> 7.8651065 | D14: =ROUND(Calculator!$G$18,2) -> 3.93 | E14: =IF(AND(B14="YES",$C$4>=D14),MOD($C$4/C14,1),"—") -> — | F14: =IF(AND(B14="YES",$C$4>=D14),ROUND(50*POWER(80,COS(PI()*MOD($C$4/C14,1))^2),0),"—") -> — | G14: =IF(B14<>"YES","—",IF($C$4<D14,"< λ/4",1500*SIN(2*PI()*MOD($C$4/C14,1)))) -> — | H14: =IF(B14<>"YES","—",IF($C$4<D14,"—",(1+SQRT((((F14)-$C$5*50)^2+(G14)^2)/(((F14)+$C$5*50)^2+(G14)^2)))/(1-SQRT((((F14)-$C$5*50)^2+(G14)^2)/(((F14)+$C$5*50)^2+(G14)^2))))) -> —
A15: =Calculator!A19 -> 15m | B15: =Calculator!$E$19 -> NO | C15: =Calculator!$F$19 -> 6.7137809 | D15: =ROUND(Calculator!$G$19,2) -> 3.36 | E15: =IF(AND(B15="YES",$C$4>=D15),MOD($C$4/C15,1),"—") -> — | F15: =IF(AND(B15="YES",$C$4>=D15),ROUND(50*POWER(80,COS(PI()*MOD($C$4/C15,1))^2),0),"—") -> — | G15: =IF(B15<>"YES","—",IF($C$4<D15,"< λ/4",1500*SIN(2*PI()*MOD($C$4/C15,1)))) -> — | H15: =IF(B15<>"YES","—",IF($C$4<D15,"—",(1+SQRT((((F15)-$C$5*50)^2+(G15)^2)/(((F15)+$C$5*50)^2+(G15)^2)))/(1-SQRT((((F15)-$C$5*50)^2+(G15)^2)/(((F15)+$C$5*50)^2+(G15)^2))))) -> —
A16: =Calculator!A20 -> 12m | B16: =Calculator!$E$20 -> NO | C16: =Calculator!$F$20 -> 5.7137129 | D16: =ROUND(Calculator!$G$20,2) -> 2.86 | E16: =IF(AND(B16="YES",$C$4>=D16),MOD($C$4/C16,1),"—") -> — | F16: =IF(AND(B16="YES",$C$4>=D16),ROUND(50*POWER(80,COS(PI()*MOD($C$4/C16,1))^2),0),"—") -> — | G16: =IF(B16<>"YES","—",IF($C$4<D16,"< λ/4",1500*SIN(2*PI()*MOD($C$4/C16,1)))) -> — | H16: =IF(B16<>"YES","—",IF($C$4<D16,"—",(1+SQRT((((F16)-$C$5*50)^2+(G16)^2)/(((F16)+$C$5*50)^2+(G16)^2)))/(1-SQRT((((F16)-$C$5*50)^2+(G16)^2)/(((F16)+$C$5*50)^2+(G16)^2))))) -> —
A17: =Calculator!A21 -> 10m | B17: =Calculator!$E$21 -> NO | C17: =Calculator!$F$21 -> 4.9393414 | D17: =ROUND(Calculator!$G$21,2) -> 2.47 | E17: =IF(AND(B17="YES",$C$4>=D17),MOD($C$4/C17,1),"—") -> — | F17: =IF(AND(B17="YES",$C$4>=D17),ROUND(50*POWER(80,COS(PI()*MOD($C$4/C17,1))^2),0),"—") -> — | G17: =IF(B17<>"YES","—",IF($C$4<D17,"< λ/4",1500*SIN(2*PI()*MOD($C$4/C17,1)))) -> — | H17: =IF(B17<>"YES","—",IF($C$4<D17,"—",(1+SQRT((((F17)-$C$5*50)^2+(G17)^2)/(((F17)+$C$5*50)^2+(G17)^2)))/(1-SQRT((((F17)-$C$5*50)^2+(G17)^2)/(((F17)+$C$5*50)^2+(G17)^2))))) -> —
A18: =Calculator!A22 -> 6m | B18: =Calculator!$E$22 -> NO | C18: =Calculator!$F$22 -> 2.7403846 | D18: =ROUND(Calculator!$G$22,2) -> 1.37 | E18: =IF(AND(B18="YES",$C$4>=D18),MOD($C$4/C18,1),"—") -> — | F18: =IF(AND(B18="YES",$C$4>=D18),ROUND(50*POWER(80,COS(PI()*MOD($C$4/C18,1))^2),0),"—") -> — | G18: =IF(B18<>"YES","—",IF($C$4<D18,"< λ/4",1500*SIN(2*PI()*MOD($C$4/C18,1)))) -> — | H18: =IF(B18<>"YES","—",IF($C$4<D18,"—",(1+SQRT((((F18)-$C$5*50)^2+(G18)^2)/(((F18)+$C$5*50)^2+(G18)^2)))/(1-SQRT((((F18)-$C$5*50)^2+(G18)^2)/(((F18)+$C$5*50)^2+(G18)^2))))) -> —
A20: 🔌 COUNTERPOISE IMPEDANCE MODEL — Real-world correction factors (inputs in blue)
A22: Parameter
A23: Counterpoise Length | C23: =Calculator!D25 -> 9.965035 | D23: m | E23: Typical: λ/4 of lowest active band (shown on Calculator sheet). Multiple radials reduce Zcp.
A24: Counterpoise Height above ground | C24: 5 | D24: m | E24: Height influences capacitive coupling to earth. Range: 0.5 m (low) → 5+ m (elevated). Higher = less ground loss.
A25: Number of Radials / Counterpoises | C25: 1 | D25: count | E25: Each additional radial roughly halves counterpoise impedance (parallel combination). 4 radials → Zcp / 4.
A27: ⚠ IMPORTANT: Z_wire model is empirical (not NEC2). R_est = 50·80^(cos²(π·L/λ½)) and X_est = 1500·sin(2π·L/λ½) are approximations. Actual feedpoint Z varies with height, soil, wire diameter, nearby objects. For accurate results, use NEC2/EZNEC simulation or a vector antenna analyzer. VSWR values here are estimates only. ⚠ VSWR 'never matches reality': this is expected — the model ignores ground loss, wire height, and end effects. Use an ATU to compensate residual mismatch.
A28: Band | B28: f center (MHz) | C28: λ/4 (m) | D28: Zcp single radial (Ω est.) | E28: Zcp with N radials (Ω) | F28: Feed Z_wire (Ω) | G28: Z_effective (Ω, corrected) | H28: VSWR corrected | I28: Correction Factor | J28: Quality Assessment
A29: =A8 -> 160m | B29: =Calculator!D12 -> 1.9 | C29: =D8 -> 37.5 | D29: =IF(B8<>"YES","—",ROUND(MIN(500,MAX(30,(100*EXP(-0.3*C$24))*(1+3*ABS(MOD(C$23/C8,1)-0.5)))),0)) -> — | E29: =IF(B8<>"YES","—",ROUND(D29/C$25,0)) -> — | F29: =IF(B8<>"YES","—",F8) -> — | G29: =IF(B8<>"YES","—",ROUND(F8+E29,0)) -> — | H29: =IF(B8<>"YES","—",IF($C$4<D8,"—",ROUND((1+SQRT(((F8+E29-$C$5*50)^2+G8^2)/((F8+E29+$C$5*50)^2+G8^2)))/(1-SQRT(((F8+E29-$C$5*50)^2+G8^2)/((F8+E29+$C$5*50)^2+G8^2))),2))) -> — | I29: =IF(OR(B8<>"YES",F8="—"),"—",ROUND(G29/F8,2)) -> — | J29: =IF(B8<>"YES","Inactive band",IF($C$4<D8,"Wire too short for this band",IF(H29<1.5,"✔ Excellent — no tuner needed",IF(H29<3,"✔ Good — most tuners handle this",IF(H29<6,"⚠ Marginal — tuner required","✗ Poor — high-loss mismatch"))))) -> Inactive band
A30: =A9 -> 80m | B30: =Calculator!D13 -> 3.65 | C30: =D9 -> 19.52 | D30: =IF(B9<>"YES","—",ROUND(MIN(500,MAX(30,(100*EXP(-0.3*C$24))*(1+3*ABS(MOD(C$23/C9,1)-0.5)))),0)) -> — | E30: =IF(B9<>"YES","—",ROUND(D30/C$25,0)) -> — | F30: =IF(B9<>"YES","—",F9) -> — | G30: =IF(B9<>"YES","—",ROUND(F9+E30,0)) -> — | H30: =IF(B9<>"YES","—",IF($C$4<D9,"—",ROUND((1+SQRT(((F9+E30-$C$5*50)^2+G9^2)/((F9+E30+$C$5*50)^2+G9^2)))/(1-SQRT(((F9+E30-$C$5*50)^2+G9^2)/((F9+E30+$C$5*50)^2+G9^2))),2))) -> — | I30: =IF(OR(B9<>"YES",F9="—"),"—",ROUND(G30/F9,2)) -> — | J30: =IF(B9<>"YES","Inactive band",IF($C$4<D9,"Wire too short for this band",IF(H30<1.5,"✔ Excellent — no tuner needed",IF(H30<3,"✔ Good — most tuners handle this",IF(H30<6,"⚠ Marginal — tuner required","✗ Poor — high-loss mismatch"))))) -> Inactive band
A31: =A10 -> 60m | B31: =Calculator!D14 -> 5.359 | C31: =D10 -> 13.3 | D31: =IF(B10<>"YES","—",ROUND(MIN(500,MAX(30,(100*EXP(-0.3*C$24))*(1+3*ABS(MOD(C$23/C10,1)-0.5)))),0)) -> — | E31: =IF(B10<>"YES","—",ROUND(D31/C$25,0)) -> — | F31: =IF(B10<>"YES","—",F10) -> — | G31: =IF(B10<>"YES","—",ROUND(F10+E31,0)) -> — | H31: =IF(B10<>"YES","—",IF($C$4<D10,"—",ROUND((1+SQRT(((F10+E31-$C$5*50)^2+G10^2)/((F10+E31+$C$5*50)^2+G10^2)))/(1-SQRT(((F10+E31-$C$5*50)^2+G10^2)/((F10+E31+$C$5*50)^2+G10^2))),2))) -> — | I31: =IF(OR(B10<>"YES",F10="—"),"—",ROUND(G31/F10,2)) -> — | J31: =IF(B10<>"YES","Inactive band",IF($C$4<D10,"Wire too short for this band",IF(H31<1.5,"✔ Excellent — no tuner needed",IF(H31<3,"✔ Good — most tuners handle this",IF(H31<6,"⚠ Marginal — tuner required","✗ Poor — high-loss mismatch"))))) -> Inactive band
A32: =A11 -> 40m | B32: =Calculator!D15 -> 7.15 | C32: =D11 -> 9.97 | D32: =IF(B11<>"YES","—",ROUND(MIN(500,MAX(30,(100*EXP(-0.3*C$24))*(1+3*ABS(MOD(C$23/C11,1)-0.5)))),0)) -> 30 | E32: =IF(B11<>"YES","—",ROUND(D32/C$25,0)) -> 30 | F32: =IF(B11<>"YES","—",F11) -> 1171 | G32: =IF(B11<>"YES","—",ROUND(F11+E32,0)) -> 1201 | H32: =IF(B11<>"YES","—",IF($C$4<D11,"—",ROUND((1+SQRT(((F11+E32-$C$5*50)^2+G11^2)/((F11+E32+$C$5*50)^2+G11^2)))/(1-SQRT(((F11+E32-$C$5*50)^2+G11^2)/((F11+E32+$C$5*50)^2+G11^2))),2))) -> 6.24 | I32: =IF(OR(B11<>"YES",F11="—"),"—",ROUND(G32/F11,2)) -> 1.03 | J32: =IF(B11<>"YES","Inactive band",IF($C$4<D11,"Wire too short for this band",IF(H32<1.5,"✔ Excellent — no tuner needed",IF(H32<3,"✔ Good — most tuners handle this",IF(H32<6,"⚠ Marginal — tuner required","✗ Poor — high-loss mismatch"))))) -> ✗ Poor — high-loss mismatch
A33: =A12 -> 30m | B33: =Calculator!D16 -> 10.125 | C33: =D12 -> 7.04 | D33: =IF(B12<>"YES","—",ROUND(MIN(500,MAX(30,(100*EXP(-0.3*C$24))*(1+3*ABS(MOD(C$23/C12,1)-0.5)))),0)) -> — | E33: =IF(B12<>"YES","—",ROUND(D33/C$25,0)) -> — | F33: =IF(B12<>"YES","—",F12) -> — | G33: =IF(B12<>"YES","—",ROUND(F12+E33,0)) -> — | H33: =IF(B12<>"YES","—",IF($C$4<D12,"—",ROUND((1+SQRT(((F12+E33-$C$5*50)^2+G12^2)/((F12+E33+$C$5*50)^2+G12^2)))/(1-SQRT(((F12+E33-$C$5*50)^2+G12^2)/((F12+E33+$C$5*50)^2+G12^2))),2))) -> — | I33: =IF(OR(B12<>"YES",F12="—"),"—",ROUND(G33/F12,2)) -> — | J33: =IF(B12<>"YES","Inactive band",IF($C$4<D12,"Wire too short for this band",IF(H33<1.5,"✔ Excellent — no tuner needed",IF(H33<3,"✔ Good — most tuners handle this",IF(H33<6,"⚠ Marginal — tuner required","✗ Poor — high-loss mismatch"))))) -> Inactive band
A34: =A13 -> 20m | B34: =Calculator!D17 -> 14.175 | C34: =D13 -> 5.03 | D34: =IF(B13<>"YES","—",ROUND(MIN(500,MAX(30,(100*EXP(-0.3*C$24))*(1+3*ABS(MOD(C$23/C13,1)-0.5)))),0)) -> 55 | E34: =IF(B13<>"YES","—",ROUND(D34/C$25,0)) -> 55 | F34: =IF(B13<>"YES","—",F13) -> 182 | G34: =IF(B13<>"YES","—",ROUND(F13+E34,0)) -> 237 | H34: =IF(B13<>"YES","—",IF($C$4<D13,"—",ROUND((1+SQRT(((F13+E34-$C$5*50)^2+G13^2)/((F13+E34+$C$5*50)^2+G13^2)))/(1-SQRT(((F13+E34-$C$5*50)^2+G13^2)/((F13+E34+$C$5*50)^2+G13^2))),2))) -> 19.93 | I34: =IF(OR(B13<>"YES",F13="—"),"—",ROUND(G34/F13,2)) -> 1.3 | J34: =IF(B13<>"YES","Inactive band",IF($C$4<D13,"Wire too short for this band",IF(H34<1.5,"✔ Excellent — no tuner needed",IF(H34<3,"✔ Good — most tuners handle this",IF(H34<6,"⚠ Marginal — tuner required","✗ Poor — high-loss mismatch"))))) -> ✗ Poor — high-loss mismatch
A35: =A14 -> 17m | B35: =Calculator!D18 -> 18.118 | C35: =D14 -> 3.93 | D35: =IF(B14<>"YES","—",ROUND(MIN(500,MAX(30,(100*EXP(-0.3*C$24))*(1+3*ABS(MOD(C$23/C14,1)-0.5)))),0)) -> — | E35: =IF(B14<>"YES","—",ROUND(D35/C$25,0)) -> — | F35: =IF(B14<>"YES","—",F14) -> — | G35: =IF(B14<>"YES","—",ROUND(F14+E35,0)) -> — | H35: =IF(B14<>"YES","—",IF($C$4<D14,"—",ROUND((1+SQRT(((F14+E35-$C$5*50)^2+G14^2)/((F14+E35+$C$5*50)^2+G14^2)))/(1-SQRT(((F14+E35-$C$5*50)^2+G14^2)/((F14+E35+$C$5*50)^2+G14^2))),2))) -> — | I35: =IF(OR(B14<>"YES",F14="—"),"—",ROUND(G35/F14,2)) -> — | J35: =IF(B14<>"YES","Inactive band",IF($C$4<D14,"Wire too short for this band",IF(H35<1.5,"✔ Excellent — no tuner needed",IF(H35<3,"✔ Good — most tuners handle this",IF(H35<6,"⚠ Marginal — tuner required","✗ Poor — high-loss mismatch"))))) -> Inactive band
A36: =A15 -> 15m | B36: =Calculator!D19 -> 21.225 | C36: =D15 -> 3.36 | D36: =IF(B15<>"YES","—",ROUND(MIN(500,MAX(30,(100*EXP(-0.3*C$24))*(1+3*ABS(MOD(C$23/C15,1)-0.5)))),0)) -> — | E36: =IF(B15<>"YES","—",ROUND(D36/C$25,0)) -> — | F36: =IF(B15<>"YES","—",F15) -> — | G36: =IF(B15<>"YES","—",ROUND(F15+E36,0)) -> — | H36: =IF(B15<>"YES","—",IF($C$4<D15,"—",ROUND((1+SQRT(((F15+E36-$C$5*50)^2+G15^2)/((F15+E36+$C$5*50)^2+G15^2)))/(1-SQRT(((F15+E36-$C$5*50)^2+G15^2)/((F15+E36+$C$5*50)^2+G15^2))),2))) -> — | I36: =IF(OR(B15<>"YES",F15="—"),"—",ROUND(G36/F15,2)) -> — | J36: =IF(B15<>"YES","Inactive band",IF($C$4<D15,"Wire too short for this band",IF(H36<1.5,"✔ Excellent — no tuner needed",IF(H36<3,"✔ Good — most tuners handle this",IF(H36<6,"⚠ Marginal — tuner required","✗ Poor — high-loss mismatch"))))) -> Inactive band
A37: =A16 -> 12m | B37: =Calculator!D20 -> 24.94 | C37: =D16 -> 2.86 | D37: =IF(B16<>"YES","—",ROUND(MIN(500,MAX(30,(100*EXP(-0.3*C$24))*(1+3*ABS(MOD(C$23/C16,1)-0.5)))),0)) -> — | E37: =IF(B16<>"YES","—",ROUND(D37/C$25,0)) -> — | F37: =IF(B16<>"YES","—",F16) -> — | G37: =IF(B16<>"YES","—",ROUND(F16+E37,0)) -> — | H37: =IF(B16<>"YES","—",IF($C$4<D16,"—",ROUND((1+SQRT(((F16+E37-$C$5*50)^2+G16^2)/((F16+E37+$C$5*50)^2+G16^2)))/(1-SQRT(((F16+E37-$C$5*50)^2+G16^2)/((F16+E37+$C$5*50)^2+G16^2))),2))) -> — | I37: =IF(OR(B16<>"YES",F16="—"),"—",ROUND(G37/F16,2)) -> — | J37: =IF(B16<>"YES","Inactive band",IF($C$4<D16,"Wire too short for this band",IF(H37<1.5,"✔ Excellent — no tuner needed",IF(H37<3,"✔ Good — most tuners handle this",IF(H37<6,"⚠ Marginal — tuner required","✗ Poor — high-loss mismatch"))))) -> Inactive band
A38: =A17 -> 10m | B38: =Calculator!D21 -> 28.85 | C38: =D17 -> 2.47 | D38: =IF(B17<>"YES","—",ROUND(MIN(500,MAX(30,(100*EXP(-0.3*C$24))*(1+3*ABS(MOD(C$23/C17,1)-0.5)))),0)) -> — | E38: =IF(B17<>"YES","—",ROUND(D38/C$25,0)) -> — | F38: =IF(B17<>"YES","—",F17) -> — | G38: =IF(B17<>"YES","—",ROUND(F17+E38,0)) -> — | H38: =IF(B17<>"YES","—",IF($C$4<D17,"—",ROUND((1+SQRT(((F17+E38-$C$5*50)^2+G17^2)/((F17+E38+$C$5*50)^2+G17^2)))/(1-SQRT(((F17+E38-$C$5*50)^2+G17^2)/((F17+E38+$C$5*50)^2+G17^2))),2))) -> — | I38: =IF(OR(B17<>"YES",F17="—"),"—",ROUND(G38/F17,2)) -> — | J38: =IF(B17<>"YES","Inactive band",IF($C$4<D17,"Wire too short for this band",IF(H38<1.5,"✔ Excellent — no tuner needed",IF(H38<3,"✔ Good — most tuners handle this",IF(H38<6,"⚠ Marginal — tuner required","✗ Poor — high-loss mismatch"))))) -> Inactive band
A39: =A18 -> 6m | B39: =Calculator!D22 -> 52 | C39: =D18 -> 1.37 | D39: =IF(B18<>"YES","—",ROUND(MIN(500,MAX(30,(100*EXP(-0.3*C$24))*(1+3*ABS(MOD(C$23/C18,1)-0.5)))),0)) -> — | E39: =IF(B18<>"YES","—",ROUND(D39/C$25,0)) -> — | F39: =IF(B18<>"YES","—",F18) -> — | G39: =IF(B18<>"YES","—",ROUND(F18+E39,0)) -> — | H39: =IF(B18<>"YES","—",IF($C$4<D18,"—",ROUND((1+SQRT(((F18+E39-$C$5*50)^2+G18^2)/((F18+E39+$C$5*50)^2+G18^2)))/(1-SQRT(((F18+E39-$C$5*50)^2+G18^2)/((F18+E39+$C$5*50)^2+G18^2))),2))) -> — | I39: =IF(OR(B18<>"YES",F18="—"),"—",ROUND(G39/F18,2)) -> — | J39: =IF(B18<>"YES","Inactive band",IF($C$4<D18,"Wire too short for this band",IF(H39<1.5,"✔ Excellent — no tuner needed",IF(H39<3,"✔ Good — most tuners handle this",IF(H39<6,"⚠ Marginal — tuner required","✗ Poor — high-loss mismatch"))))) -> Inactive band
A41: ⚠ INTERPRETATION: Z_effective = Z_wire + Zcp (series return path model). Higher Zcp (short/elevated counterpoise) increases effective feedpoint impedance, shifting the optimal UnUn ratio up. Lower Zcp (long/multiple radials, ground-mounted) approaches the infinite-ground assumption used in the main VSWR table above. Correction Factor > 1.2 indicates significant counterpoise influence — consider adding more radials or lengthening counterpoise to λ/4 of lowest active band. Note: Zcp reactance is neglected in this model (Zcp treated as purely resistive); actual VSWR may differ slightly for elevated/short counterpoises.
A43: VSWR guide: | B43: < 1.5: Excellent | C43: 1.5–3.0: Good (tuner helpful) | D43: 3.0–6.0: Marginal (tuner needed) | E43: > 6.0: Poor (high-loss mismatch)
A45: 📊 Chart below — Dashed reference thresholds: VSWR 1.5 = excellent boundary · VSWR 3.0 = tuner boundary Bars absent = inactive band or wire too short for that band

Sheet UnUn Calculator
B1: UnUn & Impedance Matching Calculator
B2: By Emiliano Gonzalez LU3VEA – lu3vea@gmail.com – License: CC0 v1.0
B4: 🎯 QUICK SELECTION — Pick antenna & band to auto-fill System Parameters below
B5: Antenna Length (m): | C5: 53.4 | D5: ← Choose Top-10 length | F5: Band: | G5: 10m | H5: ← Select band → auto-fills Operating Frequency, Load Impedance, and Wire Length
B7: 1. System Parameters (Inputs)
B8: Operating Frequency | C8: =IFERROR(INDEX(Calculator!$D$12:$D$22,MATCH(G5,Calculator!$A$12:$A$22,0)),7.1) -> 28.85 | D8: MHz [auto ↑]
B9: Target Input Impedance (Real, Rin) | C9: 50 | D9: Ohms (Ω)
B10: Target Input Impedance (Imag, Xin) | C10: 0 | D10: Ohms (Ω)
B11: Output / Load Impedance (Real, Rout) | C11: =IFERROR(ROUND(50*POWER(80,POWER(COS(PI()*C5/INDEX(Calculator!$F$12:$F$22,MATCH(G5,Calculator!$A$12:$A$22,0))),2)),0),450) -> 1017 | D11: Ω [auto ↑]
B12: Output / Load Impedance (Imag, Xout) | C12: =IFERROR(ROUND(1500*SIN(2*PI()*C5/INDEX(Calculator!$F$12:$F$22,MATCH(G5,Calculator!$A$12:$A$22,0))),0),150) -> -1391 | D12: Ω [auto ↑]
B13: Toroid Core Selection | C13: T-200-2
B14: Primary Winding Turns (Np) | C14: 20 | D14: Turns
B15: Wire Winding Diameter | C15: 2 | D15: mm
B17: 2. UnUn Transformer Properties
B18: Impedance Ratio (Rout / Rin) | C18: =C11/C9 -> 20.34 | D18: : 1 | E18: ← Uses resistive part only. Correct: match R, then separately cancel X with series L/C.. For complex load ideal UnUn targets Rin=Rout.
B19: Turns Ratio (Ns / Np) | C19: =SQRT(C18) -> 4.5099889
B20: Calculated Secondary Turns (Ns) | C20: =C14*C19 -> 90.199778 | D20: Turns
B21: Actual Secondary Turns (Rounded) | C21: =ROUND(C20, 0) -> 90 | D21: Turns | E21: =ROUND(0.8*((PI()*VLOOKUP(C13,Toroid_Database!A:F, 5, FALSE()))/C15),0) -> 40 | F21: =IF(C21>E21,"⛔ ERROR: Ns="&TEXT(C21,"0")&" EXCEEDS core max of "&TEXT(E21,"0")&" turns! Use larger core or reduce impedance ratio.","✔ OK — Ns within limit | ← Max turns allowed: "&TEXT(E21,"0")) -> ⛔ ERROR: Ns=90 EXCEEDS core max of 40 turns! Use larger core or reduce impedance ratio.
B22: Actual Impedance Ratio (Based on Turns) | C22: =(C21/C14)^2 -> 20.25 | D22: : 1
B23: Transformed Load Reactance (Seen at Input) | C23: =C12/C22 -> -68.691358 | D23: Ohms (Ω)
B25: 2.1 Winding Parameters Autotransformer
B26: Total Winding Turns (Nt) | C26: =C21 -> 90 | D26: Turns | E26: ← Full winding turns = Ns (Actual Secondary Turns from Section 2)
B27: Tap Turns for Input (N_tap) | C27: =C14 -> 20 | D27: Turns | E27: ← Input tap = Np (Primary Turns, Section 1). Feed coax at 0–N_tap turns; antenna across full winding 0–Nt.
B28: Turns Above Tap (Nt − N_tap) | C28: =C26-C27 -> 70 | D28: Turns | E28: ← Winding turns from tap to end of coil (antenna side)
B29: Impedance Ratio Check (Nt/N_tap)² | C29: =(C26/C27)^2 -> 20.25 | D29: : 1 | E29: ← Must match Actual Impedance Ratio (C21). Verifies tap calculation is consistent.
B30: Approx. Wire Length per Turn (m) | C30: =ROUND(PI()*((VLOOKUP(C13,Toroid_Database!A:F,4,FALSE())+VLOOKUP(C13,Toroid_Database!A:F,5,FALSE()))/2)/1000,3) -> 0.13 | D30: m / turn | E30: ← Estimated: π × (mean toroid diameter = (OD+ID)/2). Actual varies with wire diameter & winding style.
B31: Total Wire Length Required (m) | C31: =ROUND(C26*C30,2) -> 11.7 | D31: m | E31: ← Nt × wire-per-turn. Add 15–20 cm extra for terminations.
B33: 3. Reactance Compensation (Matching)
B34: To achieve a perfect match, the imaginary part of the load must be neutralized. This is typically done by adding series reactance at the load side before the UnUn.
B35: Required Compensation Reactance (Xcomp) | C35: =-C12 -> 1391 | D35: Ohms (Ω)
B36: Component Type Needed | C36: =IF(C35>0, "Inductor (Series L)", IF(C35<0, "Capacitor (Series C)", "None")) -> Inductor (Series L)
B37: Component Value (L or C) | C37: =IF(C35>0, C35/(2*PI()*C8), IF(C35<0, 1000000/(2*PI()*C8*ABS(C35)), 0)) -> 7.6736404 | D37: =IF(C35>0,ROUND(C37,0),IF(C35<0,INDEX({1,1.1,1.2,1.3,1.5,1.6,1.8,2,2.2,2.4,2.7,3,3.3,3.6,3.9,4.3,4.7,5.1,5.6,6.2,6.8,7.5,8.2,9.1},MATCH(MIN(ABS({1,1.1,1.2,1.3,1.5,1.6,1.8,2,2.2,2.4,2.7,3,3.3,3.6,3.9,4.3,4.7,5.1,5.6,6.2,6.8,7.5,8.2,9.1}-C37/POWER(10,INT(LOG10(C37))))),ABS({1,1.1,1.2,1.3,1.5,1.6,1.8,2,2.2,2.4,2.7,3,3.3,3.6,3.9,4.3,4.7,5.1,5.6,6.2,6.8,7.5,8.2,9.1}-C37/POWER(10,INT(LOG10(C37)))),0))*POWER(10,INT(LOG10(C37))),0)) -> 8 | E37: ← Standard value (L: Round, C: Std 5%)
B38: Unit | C38: =IF(C35>0, "µH", IF(C35<0, "pF", "-")) -> µH
B40: 4. Toroid Magnetics & Design Check
B41: Core AL Value | C41: =VLOOKUP(C13,Toroid_Database!A:F, 3, FALSE()) -> 12 | D41: nH/N²
B42: Primary Inductance (Lp) | C42: =C41*(C14^2)/1000 -> 4.8 | D42: µH
B43: Primary Reactance (XLp) @ Freq | C43: =2*PI()*C8*C42 -> 870.0955 | D43: Ohms (Ω)
B44: Design Check (Rule of Thumb: XLp > 4*Rin) | C44: =IF(C43 >= (4*C9), "ADEQUATE", "WARNING: INCREASE PRIMARY TURNS") -> ADEQUATE
B46: Note: Primary reactance (XLp) should generally be at least 4 to 5 times the input impedance (e.g., > 200Ω for a 50Ω system) to prevent the transformer from loading down the source.
B48: 5. Counterpoise Impedance Analysis
...

Sheet Transmatch Calculator
B2: AIR-CORE TRANSMATCH CALCULATOR
B3: By Emiliano Gonzalez LU3VEA – lu3vea@gmail.com – License: CC0 v1.0
B5: Antenna Length (m): | C5: 23.4 | D5: ← Choose Top-10 length
B7: GLOBAL SETTINGS
B8: Parameter | C8: Value | D8: Unit | E8: Notes
B9: Target Output Impedance (Ω) | C9: 50 | D9: Ω | E9: Fixed 50Ω output (e.g. coax / transmatch)
B10: Wire Diameter | C10: 1 | D10: mm | E10: Winding wire diameter incl. insulation
B11: Core Diameter | C11: 50 | D11: mm | E11: Outer diameter of winding form (coil former)
B12: Number of Active Taps | C12: =COUNTIF(Calculator!E12:E22,"YES") -> 2 | D12: # | E12: Active bands
B13: Turns at 50Ω tap | C13: 5 | D13: =IFERROR(MAX(CEILING(5/MIN(D61:D71),1),CEILING((5*C119*(C108/25.4)+SQRT(C119*(25*C119*(C108/25.4)^2+C115^2*(9*C115-10*(C108/25.4)+10*(C10/25.4)))))/(C115^2*MAX(D61:D71)),1)),5) -> 3 | E13: Min turns
B14: Space between coil turns | C14: 1
B16: TAP INPUT IMPEDANCES
B17: Tap # | C17: Frequency | D17: R (Ω) Resistance | E17: X (Ω) Reactance (+L / −C) | F17: Active
B18: 1 | C18: {=IFERROR(INDEX(Calculator!$D$12:$D$22,SMALL(IF(Calculator!$E$12:$E$22="YES",ROW(Calculator!$D$12:$D$22)-ROW(Calculator!$D$12)+1),1),1),"")} -> 7.15 | D18: =IF(C18="","",IFERROR(ROUND(50*POWER(80,COS(PI()*MOD($C$5/INDEX(Calculator!$F$12:$F$22,MATCH(C18,Calculator!$D$12:$D$22,0)),1))^2),0),"")) -> 1223 | E18: =IF(C18="","",IFERROR(ROUND(1500*SIN(2*PI()*MOD($C$5/INDEX(Calculator!$F$12:$F$22,MATCH(C18,Calculator!$D$12:$D$22,0)),1)),0),"")) -> 1333 | F18: =IF(ROW()-17<=$C$12,"YES","NO") -> YES
B19: 2 | C19: {=IFERROR(INDEX(Calculator!$D$12:$D$22,SMALL(IF(Calculator!$E$12:$E$22="YES",ROW(Calculator!$D$12:$D$22)-ROW(Calculator!$D$12)+1),2),1),"")} -> 14.175 | D19: =IF(C19="","",IFERROR(ROUND(50*POWER(80,COS(PI()*MOD($C$5/INDEX(Calculator!$F$12:$F$22,MATCH(C19,Calculator!$D$12:$D$22,0)),1))^2),0),"")) -> 160 | E19: =IF(C19="","",IFERROR(ROUND(1500*SIN(2*PI()*MOD($C$5/INDEX(Calculator!$F$12:$F$22,MATCH(C19,Calculator!$D$12:$D$22,0)),1)),0),"")) -> 1325 | F19: =IF(ROW()-17<=$C$12,"YES","NO") -> YES
B20: 3 | C20: {=IFERROR(INDEX(Calculator!$D$12:$D$22,SMALL(IF(Calculator!$E$12:$E$22="YES",ROW(Calculator!$D$12:$D$22)-ROW(Calculator!$D$12)+1),3),1),"")} | D20: =IF(C20="","",IFERROR(ROUND(50*POWER(80,COS(PI()*MOD($C$5/INDEX(Calculator!$F$12:$F$22,MATCH(C20,Calculator!$D$12:$D$22,0)),1))^2),0),"")) | E20: =IF(C20="","",IFERROR(ROUND(1500*SIN(2*PI()*MOD($C$5/INDEX(Calculator!$F$12:$F$22,MATCH(C20,Calculator!$D$12:$D$22,0)),1)),0),"")) | F20: =IF(ROW()-17<=$C$12,"YES","NO") -> NO
B21: 4 | C21: {=IFERROR(INDEX(Calculator!$D$12:$D$22,SMALL(IF(Calculator!$E$12:$E$22="YES",ROW(Calculator!$D$12:$D$22)-ROW(Calculator!$D$12)+1),4),1),"")} | D21: =IF(C21="","",IFERROR(ROUND(50*POWER(80,COS(PI()*MOD($C$5/INDEX(Calculator!$F$12:$F$22,MATCH(C21,Calculator!$D$12:$D$22,0)),1))^2),0),"")) | E21: =IF(C21="","",IFERROR(ROUND(1500*SIN(2*PI()*MOD($C$5/INDEX(Calculator!$F$12:$F$22,MATCH(C21,Calculator!$D$12:$D$22,0)),1)),0),"")) | F21: =IF(ROW()-17<=$C$12,"YES","NO") -> NO
B22: 5 | C22: {=IFERROR(INDEX(Calculator!$D$12:$D$22,SMALL(IF(Calculator!$E$12:$E$22="YES",ROW(Calculator!$D$12:$D$22)-ROW(Calculator!$D$12)+1),5),1),"")} | D22: =IF(C22="","",IFERROR(ROUND(50*POWER(80,COS(PI()*MOD($C$5/INDEX(Calculator!$F$12:$F$22,MATCH(C22,Calculator!$D$12:$D$22,0)),1))^2),0),"")) | E22: =IF(C22="","",IFERROR(ROUND(1500*SIN(2*PI()*MOD($C$5/INDEX(Calculator!$F$12:$F$22,MATCH(C22,Calculator!$D$12:$D$22,0)),1)),0),"")) | F22: =IF(ROW()-17<=$C$12,"YES","NO") -> NO
B23: 6 | C23: {=IFERROR(INDEX(Calculator!$D$12:$D$22,SMALL(IF(Calculator!$E$12:$E$22="YES",ROW(Calculator!$D$12:$D$22)-ROW(Calculator!$D$12)+1),6),1),"")} | D23: =IF(C23="","",IFERROR(ROUND(50*POWER(80,COS(PI()*MOD($C$5/INDEX(Calculator!$F$12:$F$22,MATCH(C23,Calculator!$D$12:$D$22,0)),1))^2),0),"")) | E23: =IF(C23="","",IFERROR(ROUND(1500*SIN(2*PI()*MOD($C$5/INDEX(Calculator!$F$12:$F$22,MATCH(C23,Calculator!$D$12:$D$22,0)),1)),0),"")) | F23: =IF(ROW()-17<=$C$12,"YES","NO") -> NO
B24: 7 | C24: {=IFERROR(INDEX(Calculator!$D$12:$D$22,SMALL(IF(Calculator!$E$12:$E$22="YES",ROW(Calculator!$D$12:$D$22)-ROW(Calculator!$D$12)+1),7),1),"")} | D24: =IF(C24="","",IFERROR(ROUND(50*POWER(80,COS(PI()*MOD($C$5/INDEX(Calculator!$F$12:$F$22,MATCH(C24,Calculator!$D$12:$D$22,0)),1))^2),0),"")) | E24: =IF(C24="","",IFERROR(ROUND(1500*SIN(2*PI()*MOD($C$5/INDEX(Calculator!$F$12:$F$22,MATCH(C24,Calculator!$D$12:$D$22,0)),1)),0),"")) | F24: =IF(ROW()-17<=$C$12,"YES","NO") -> NO
B25: 8 | C25: {=IFERROR(INDEX(Calculator!$D$12:$D$22,SMALL(IF(Calculator!$E$12:$E$22="YES",ROW(Calculator!$D$12:$D$22)-ROW(Calculator!$D$12)+1),8),1),"")} | D25: =IF(C25="","",IFERROR(ROUND(50*POWER(80,COS(PI()*MOD($C$5/INDEX(Calculator!$F$12:$F$22,MATCH(C25,Calculator!$D$12:$D$22,0)),1))^2),0),"")) | E25: =IF(C25="","",IFERROR(ROUND(1500*SIN(2*PI()*MOD($C$5/INDEX(Calculator!$F$12:$F$22,MATCH(C25,Calculator!$D$12:$D$22,0)),1)),0),"")) | F25: =IF(ROW()-17<=$C$12,"YES","NO") -> NO
B26: 9 | C26: {=IFERROR(INDEX(Calculator!$D$12:$D$22,SMALL(IF(Calculator!$E$12:$E$22="YES",ROW(Calculator!$D$12:$D$22)-ROW(Calculator!$D$12)+1),9),1),"")} | D26: =IF(C26="","",IFERROR(ROUND(50*POWER(80,COS(PI()*MOD($C$5/INDEX(Calculator!$F$12:$F$22,MATCH(C26,Calculator!$D$12:$D$22,0)),1))^2),0),"")) | E26: =IF(C26="","",IFERROR(ROUND(1500*SIN(2*PI()*MOD($C$5/INDEX(Calculator!$F$12:$F$22,MATCH(C26,Calculator!$D$12:$D$22,0)),1)),0),"")) | F26: =IF(ROW()-17<=$C$12,"YES","NO") -> NO
B27: 10 | C27: {=IFERROR(INDEX(Calculator!$D$12:$D$22,SMALL(IF(Calculator!$E$12:$E$22="YES",ROW(Calculator!$D$12:$D$22)-ROW(Calculator!$D$12)+1),10),1),"")} | D27: =IF(C27="","",IFERROR(ROUND(50*POWER(80,COS(PI()*MOD($C$5/INDEX(Calculator!$F$12:$F$22,MATCH(C27,Calculator!$D$12:$D$22,0)),1))^2),0),"")) | E27: =IF(C27="","",IFERROR(ROUND(1500*SIN(2*PI()*MOD($C$5/INDEX(Calculator!$F$12:$F$22,MATCH(C27,Calculator!$D$12:$D$22,0)),1)),0),"")) | F27: =IF(ROW()-17<=$C$12,"YES","NO") -> NO
B28: 11 | C28: {=IFERROR(INDEX(Calculator!$D$12:$D$22,SMALL(IF(Calculator!$E$12:$E$22="YES",ROW(Calculator!$D$12:$D$22)-ROW(Calculator!$D$12)+1),11),1),"")} | D28: =IF(C28="","",IFERROR(ROUND(50*POWER(80,COS(PI()*MOD($C$5/INDEX(Calculator!$F$12:$F$22,MATCH(C28,Calculator!$D$12:$D$22,0)),1))^2),0),"")) | E28: =IF(C28="","",IFERROR(ROUND(1500*SIN(2*PI()*MOD($C$5/INDEX(Calculator!$F$12:$F$22,MATCH(C28,Calculator!$D$12:$D$22,0)),1)),0),"")) | F28: =IF(ROW()-17<=$C$12,"YES","NO") -> NO
B30: SUMMARY DASHBOARD
B31: All key results in one place. Go to individual sheets to adjust inputs.
B33: KEY PARAMETERS
B34: Target Z_out | C34: =C9 -> 50 | D34: Ω
B35: Wire Dia. | C35: =C10 -> 1 | D35: mm
B36: T_ref turns | C36: =C13 -> 5 | D36: turns
B37: Active taps | C37: =C12 -> 2 | D37: #
B38: Total wire | C38: =I73 -> 6569.0702 | D38: mm
B39: Inductance L | C39: =IFERROR(C117,"—") -> 22.238007 | D39: µH
B40: L sufficient? | C40: =IFERROR(C120,"—") -> ✔ YES
B42: TAP SUMMARY — ALL ACTIVE TAPS
B43: Tap # | C43: Frequency (MHz) | D43: Z_in (Ω) | E43: Phase (°) | F43: Turns Ratio | G43: Cum. Turns | H43: SWR | I43: Return Loss (dB) | J43: Refl. Power (%) | K43: Series L (µH) | L43: Series C (pF) | M43: Shunt L (µH) | N43: Shunt C (pF) | O43: Series L (nH) | P43: Series C E24 (pF) | Q43: Shunt L (nH) | R43: Shunt C E24 (pF) | S43: SWR with 5% comp Serial | AA43: E24 Table (pF helper)
B44: 1 | C44: =C18 -> 7.15 | D44: =D80 -> 1809.0379 | E44: =E80 -> 47.46426 | F44: =D61 -> 4.9457052 | G44: =E61 -> 25 | H44: =F80 -> 2.8352759 | I44: =G80 -> 6.4019051 | J44: =I80 -> 22.89863 | K44: =IF(D44<>"",G134,"—") -> — | L44: =IF(D44<>"",H134,"—") -> 408.4514 | M44: =IF(D44<>"",I134,"—") -> — | N44: =IF(D44<>"",J134,"—") -> 221.77132 | O44: =IF(ISNUMBER(K44),ROUND(K44*1000,0),"—") -> — | P44: =IF(ISNUMBER(L44),LOOKUP(2,1/(ABS($AA$44:$AA$164-L44)=MIN(ABS($AA$44:$AA$164-L44))),$AA$44:$AA$164),"—") -> 390 | Q44: =IF(ISNUMBER(M44),ROUND(M44*1000,0),"—") -> — | R44: =IF(ISNUMBER(N44),LOOKUP(2,1/(ABS($AA$44:$AA$164-N44)=MIN(ABS($AA$44:$AA$164-N44))),$AA$44:$AA$164),"—") -> 220 | S44: =IF(D44="","—",IFERROR((1+ABS(0.05*E18*$C$9/D18)/SQRT(4*$C$9^2+(0.05*E18*$C$9/D18)^2))/(1-ABS(0.05*E18*$C$9/D18)/SQRT(4*$C$9^2+(0.05*E18*$C$9/D18)^2)),"—")) -> 1.0560023 | AA44: 1
B45: 2 | C45: =C19 -> 14.175 | D45: =D81 -> 1334.6254 | E45: =E81 -> 83.114602 | F45: =D62 -> 1.7888544 | G45: =E62 -> 9 | H45: =F81 -> 70.56493 | I45: =G81 -> 0.24619797 | J45: =I81 -> 94.488772 | K45: =IF(D45<>"",G135,"—") -> — | L45: =IF(D45<>"",H135,"—") -> 27.116346 | M45: =IF(D45<>"",I135,"—") -> — | N45: =IF(D45<>"",J135,"—") -> 26.726626 | O45: =IF(ISNUMBER(K45),ROUND(K45*1000,0),"—") -> — | P45: =IF(ISNUMBER(L45),LOOKUP(2,1/(ABS($AA$44:$AA$164-L45)=MIN(ABS($AA$44:$AA$164-L45))),$AA$44:$AA$164),"—") -> 27 | Q45: =IF(ISNUMBER(M45),ROUND(M45*1000,0),"—") -> — | R45: =IF(ISNUMBER(N45),LOOKUP(2,1/(ABS($AA$44:$AA$164-N45)=MIN(ABS($AA$44:$AA$164-N45))),$AA$44:$AA$164),"—") -> 27 | S45: =IF(D45="","—",IFERROR((1+ABS(0.05*E19*$C$9/D19)/SQRT(4*$C$9^2+(0.05*E19*$C$9/D19)^2))/(1-ABS(0.05*E19*$C$9/D19)/SQRT(4*$C$9^2+(0.05*E19*$C$9/D19)^2)),"—")) -> 1.508567 | AA45: 1.1
B46: 3 | C46: =C20 | D46: =D82 | E46: =E82 | F46: =D63 | G46: =E63 | H46: =F82 | I46: =G82 | J46: =I82 | K46: =IF(D46<>"",G136,"—") -> — | L46: =IF(D46<>"",H136,"—") -> — | M46: =IF(D46<>"",I136,"—") -> — | N46: =IF(D46<>"",J136,"—") -> — | O46: =IF(ISNUMBER(K46),ROUND(K46*1000,0),"—") -> — | P46: =IF(ISNUMBER(L46),LOOKUP(2,1/(ABS($AA$44:$AA$164-L46)=MIN(ABS($AA$44:$AA$164-L46))),$AA$44:$AA$164),"—") -> — | Q46: =IF(ISNUMBER(M46),ROUND(M46*1000,0),"—") -> — | R46: =IF(ISNUMBER(N46),LOOKUP(2,1/(ABS($AA$44:$AA$164-N46)=MIN(ABS($AA$44:$AA$164-N46))),$AA$44:$AA$164),"—") -> — | S46: =IF(D46="","—",IFERROR((1+ABS(0.05*E20*$C$9/D20)/SQRT(4*$C$9^2+(0.05*E20*$C$9/D20)^2))/(1-ABS(0.05*E20*$C$9/D20)/SQRT(4*$C$9^2+(0.05*E20*$C$9/D20)^2)),"—")) -> — | AA46: 1.2
B47: 4 | C47: =C21 | D47: =D83 | E47: =E83 | F47: =D64 | G47: =E64 | H47: =F83 | I47: =G83 | J47: =I83 | K47: =IF(D47<>"",G137,"—") -> — | L47: =IF(D47<>"",H137,"—") -> — | M47: =IF(D47<>"",I137,"—") -> — | N47: =IF(D47<>"",J137,"—") -> — | O47: =IF(ISNUMBER(K47),ROUND(K47*1000,0),"—") -> — | P47: =IF(ISNUMBER(L47),LOOKUP(2,1/(ABS($AA$44:$AA$164-L47)=MIN(ABS($AA$44:$AA$164-L47))),$AA$44:$AA$164),"—") -> — | Q47: =IF(ISNUMBER(M47),ROUND(M47*1000,0),"—") -> — | R47: =IF(ISNUMBER(N47),LOOKUP(2,1/(ABS($AA$44:$AA$164-N47)=MIN(ABS($AA$44:$AA$164-N47))),$AA$44:$AA$164),"—") -> — | S47: =IF(D47="","—",IFERROR((1+ABS(0.05*E21*$C$9/D21)/SQRT(4*$C$9^2+(0.05*E21*$C$9/D21)^2))/(1-ABS(0.05*E21*$C$9/D21)/SQRT(4*$C$9^2+(0.05*E21*$C$9/D21)^2)),"—")) -> — | AA47: 1.3
...

Sheet NEC2 Export
A1: 📡 NEC2 Export — Long Wire Antenna Simulation File Generator
A2: By Emiliano Gonzalez LU3VEA – lu3vea@gmail.com – License: CC0 v1.0 | v1.1 Fixed: vertical CP segment count bug
A4: ⚙ SIMULATION PARAMETERS — Blue cells are editable inputs
A5: Wire Length | B5: =IFERROR(IF(ISNUMBER(INDEX(Calculator!$B$29:$B$38,E5)),INDEX(Calculator!$B$29:$B$38,E5),0),0) -> 13.3 | C5: m | D5: Select antenna | E5: 1 | F5: ← Rank (1–10) | G5: =INDEX(Calculator!$E$29:$E$38,E5) -> ★★★ EXCELLENT | H5: =IFERROR("Score "&TEXT(INDEX(Calculator!$D$29:$D$38,E5),"0.000")&" · "&INDEX(Calculator!$G$29:$G$38,E5),"") -> Score 0.153 · Portable / SOTA
A6: Counterpoise Length | B6: =IFERROR(IF(ISNUMBER(Calculator!D25),Calculator!D25,0),0) -> 9.965035 | C6: m | D6: λ/4 of lowest active band. Set to 0 to omit counterpoise.
A7: Wire Height above ground | B7: 5 | C7: m | D7: Antenna wire height. Typical: 5–15 m for portable, 10–30 m for home station.
A8: Wire Diameter | B8: 1 | C8: mm | D8: Conductor diameter. Typical: 1.0 mm (20 AWG), 2.05 mm (12 AWG), 3.26 mm (8 AWG).
A9: Wire Conductivity | B9: 58000000 | C9: S/m | D9: Copper: 5.8×10⁷. Aluminium: 3.5×10⁷. Steel: 1.0×10⁷.
A10: Segments (antenna wire) | B10: =MAX(11,2*INT(B5*B15/30/2)+1) -> 11 | C10: - | D10: NEC2 rule: segment length ≤ λ/10 at highest frequency. Formula: MAX(11, 2×INT(L×f/30/2)+1).
A11: Segments (counterpoise) | B11: =IF(B6>0,MAX(7,2*INT(B6*B15/30/2)+1),0) -> 7 | C11: - | D11: Segments for HORIZONTAL counterpoise wire. NEC2 rule: ≤ λ/10 at highest frequency. 0 if no counterpoise.
A12: Ground Type | B12: Real (Sommerfeld-Norton) | C12: - | D12: Options: "Free Space", "Perfect Ground", "Real (Sommerfeld-Norton)"
A13: Ground Conductivity | B13: 0.005 | C13: S/m | D13: Typical soil: 0.001–0.03. Good ground: 0.03. Sea water: 5.0.
A14: Ground Permittivity | B14: 13 | C14: εr | D14: Typical soil: 10–20. Rocky: 7. Sea water: 80.
A15: Highest Sim. Freq. | B15: =IFERROR(SUMPRODUCT(MAX((Calculator!E12:E22="YES")*Calculator!C12:C22)),28) -> 14.35 | C15: MHz | D15: Auto-filled: highest active band upper edge. Used for segment count.
A16: Lowest Sim. Freq. | B16: =IFERROR(SUMPRODUCT(MIN(IF(Calculator!E12:E22="YES",Calculator!B12:B22,1000000000))),7) -> 7 | C16: MHz | D16: Auto-filled: lowest active band lower edge.
A17: Frequency Step | B17: 0.5 | C17: MHz | D17: Sweep step.
A18: Source Impedance | B18: 50 | C18: Ω | D18: Reference impedance for VSWR calculation. Standard: 50 Ω.
A19: Source Power | B19: 100 | C19: W | D19: Transmit power for field strength calculations.
A21: NEC2 INPUT DECK — COUNTERPOISE HORIZONTAL (IN-LINE with antenna) — Copy everything in column A below the dashed line into a .nec file
A22: # | B22: Tag / Wire | C22: X1 (m) | D22: Y1 (m) | E22: Z1 (m) | F22: X2 (m) | G22: Y2 (m) | H22: Z2 (m) / Notes
A23: 1 | B23: Antenna wire | C23: =-(B5/2) -> -6.65 | D23: 0 | E23: =B7 -> 5 | F23: =(B5/2) -> 6.65 | G23: 0 | H23: =B7 -> 5
A24: 2 | B24: Counterpoise | C24: =IF(B6>0,-(B5/2+B6),0) -> -16.615035 | D24: 0 | E24: =IF(B6>0,B7,"") -> 5 | F24: =IF(B6>0,-(B5/2),0) -> -6.65 | G24: 0 | H24: =IF(B6>0,B7,"") -> 5
A26: ="CM Long Wire Antenna — NEC2 Model" -> CM Long Wire Antenna — NEC2 Model | B26: Comment: model title
A27: ="CM Wire length: "&TEXT(B5,"0.0")&" m | Counterpoise: "&TEXT(B6,"0.0")&" m | Height: "&TEXT(B7,"0.0")&" m" -> CM Wire length: 13.3 m | Counterpoise: 10.0 m | Height: 5.0 m | B27: Comment: dimensions
A28: ="CM Wire diameter: "&TEXT(B8,"0.0")&" mm | Conductivity: "&TEXT(B9,"0.00E+0")&" S/m" -> CM Wire diameter: 1.0 mm | Conductivity: 5.80E+7 S/m | B28: Comment: conductor
A29: ="CM Frequency sweep: "&TEXT(B16,"0.00")&" – "&TEXT(B16+(CEILING((B15-B16)/B17,1))*B17,"0.00")&" MHz step "&TEXT(B17,"0.00")&" MHz" -> CM Frequency sweep: 7.00 – 14.50 MHz step 0.50 MHz | B29: Comment: frequency
A30: ="CM Generated by Long Wire Antenna Calculator – LU3VEA" -> CM Generated by Long Wire Antenna Calculator – LU3VEA | B30: Comment: source
A31: ="CE" -> CE | B31: CE = end of comments
A32: =IFERROR("GW 1 "&SUBSTITUTE(TEXT(B10,"0"),",",".")&" "&SUBSTITUTE(TEXT(-B5/2,"0.0000"),",",".")&" 0.0000 "&SUBSTITUTE(TEXT(B7,"0.0000"),",",".")&" "&SUBSTITUTE(TEXT(B5/2,"0.0000"),",",".")&" 0.0000 "&SUBSTITUTE(TEXT(B7,"0.0000"),",",".")&" "&SUBSTITUTE(TEXT(B8/2000,"0.00000"),",","."),"!!! ERROR: Wire Length (B5) is not a valid number. Recalculate the workbook first.") -> GW 1 11 -6.6500 0.0000 5.0000 6.6500 0.0000 5.0000 0.00050 | B32: GW tag=1: antenna wire. Format: GW tag segs X1 Y1 Z1 X2 Y2 Z2 radius(m)
A33: =IFERROR(IF(B6>0,"GW 2 "&SUBSTITUTE(TEXT(B11,"0"),",",".")&" "&SUBSTITUTE(TEXT(-(B5/2+B6),"0.0000"),",",".")&" 0.0000 "&SUBSTITUTE(TEXT(B7,"0.0000"),",",".")&" "&SUBSTITUTE(TEXT(-B5/2,"0.0000"),",",".")&" 0.0000 "&SUBSTITUTE(TEXT(B7,"0.0000"),",",".")&" "&SUBSTITUTE(TEXT(B8/2000,"0.00000"),",","."),"CM (no counterpoise — B6=0)"),"!!! ERROR: Check Wire/Counterpoise inputs (B5, B6)") -> GW 2 7 -16.6150 0.0000 5.0000 -6.6500 0.0000 5.0000 0.00050 | B33: GW tag=2: counterpoise. Omitted (CM comment) when counterpoise length = 0.
A34: =IF(B12="Free Space","GE 0","GE 1") -> GE 1 | B34: GE: 0 = free space, 1 = ground present. Auto from Ground Type.
A35: =IFERROR("LD 5 1 1 "&SUBSTITUTE(TEXT(B10,"0"),",",".")&" "&SUBSTITUTE(TEXT(B9,"0.000E+00"),",","."),"!!! ERROR: Check segment count (B10)") -> LD 5 1 1 11 5.800E+07 | B35: LD type=5: wire conductivity load on all segments of antenna (tag 1). Without this NEC2 assumes perfect (lossless) conductor.
A36: =IFERROR(IF(B6>0,"LD 5 2 1 "&SUBSTITUTE(TEXT(B11,"0"),",",".")&" "&SUBSTITUTE(TEXT(B9,"0.000E+00"),",","."),"CM (no LD 5 for counterpoise — no counterpoise)"),"!!! ERROR: Check segment count (B11)") -> LD 5 2 1 7 5.800E+07 | B36: LD type=5: wire conductivity load on counterpoise (tag 2). Omitted if counterpoise length = 0.
A37: ="EX 0 1 1 0 1 0" -> EX 0 1 1 0 1 0 | B37: EX: voltage source at feedpoint (end segment 1 of antenna wire tag 1). End-fed: source at wire end, not centre.
A38: =IF(B12="Free Space","GN -1",IF(B12="Perfect Ground","GN 1","GN 2 0 0 0 "&SUBSTITUTE(TEXT(B14,"0.0"),",",".")&" "&SUBSTITUTE(TEXT(B13,"0.000"),",","."))) -> GN 2 0 0 0 13.0 0.005 | B38: GN: ground type. -1=free space, 1=perfect, 2=real (Sommerfeld-Norton) with εr and σ.
A39: =IFERROR("FR 0 "&SUBSTITUTE(TEXT(CEILING((B15-B16)/B17,1)+1,"0"),",",".")&" 0 0 "&SUBSTITUTE(TEXT(B16,"0.000"),",",".")&" "&SUBSTITUTE(TEXT(B17,"0.000"),",","."),"!!! ERROR: Check frequency settings (B15/B16/B17)") -> FR 0 16 0 0 7.000 0.500 | B39: FR: linear frequency sweep. NFRQ=CEILING((fHigh-fLow)/step,1)+1; actual sweep end = fLow+(NFRQ-1)×step (may exceed fHigh by <1 step). Format: FR type steps 0 0 fStart fStep(MHz).
A40: ="RP 0 1 361 1000 90 0 0 1" -> RP 0 1 361 1000 90 0 0 1 | B40: RP: azimuth radiation pattern. 1 elevation angle (90°=horizon), 361 azimuth steps, 1° step.
A41: ="EN" -> EN | B41: EN: end of NEC2 input file.
A43: NEC2 INPUT DECK — ANTENNA HORIZONTAL + COUNTERPOISE VERTICAL — Copy everything in column A below the dashed line into a .nec file
A44: # | B44: Tag / Wire | C44: X1 (m) | D44: Y1 (m) | E44: Z1 (m) | F44: X2 (m) | G44: Y2 (m) | H44: Z2 (m) / Notes
...

Sheet Length Sweep
A1: 📊 Wire Length Sweep 5.0 – 60.0 m (step 0.1 m) — Resonance Avoidance Score · GREEN rows = recommended
A2: By Emiliano Gonzalez LU3VEA – lu3vea@gmail.com – License: CC0 v1.0
A4: Score = worst-case (minimum) resonance-avoidance fraction across ALL active bands and the FULL band span. 0.25 = perfect (mid-gap between λ/4 and λ/2), 0.00 = on resonance anywhere in the band. Inactive bands return 1.00 (not counted). CORRECTED: formula evaluates at both band edges (f Low & f High) and analytically detects any λ/2 or λ/4 resonance falling inside the full [f Low, f High] window — if one exists the band score is 0. ⚠ Both λ/2 (very high Z, >2000 Ω) AND λ/4 (very low Z) are penalised. Previous version used only f Center, missing resonances at band edges.
A5: ⚠ Change band ACTIVE selection on the 'Calculator' sheet — this table updates automatically!
A6: Wire Length (m) | B6: 160m score | C6: 80m score | D6: 60m score | E6: 40m score | F6: 30m score | G6: 20m score | H6: 17m score | I6: 15m score | J6: 12m score | K6: 10m score | L6: 6m score | M6: OVERALL Score | N6: Rank | O6: Quality Rating
