Workbook

Sheet Calculator
A1: 📡 Long Wire Antenna + 9:1 UnUn — Multi-Band Optimizer
A2: Select YES/NO for each band · Adjust Velocity Factor · See 'Length Sweep' sheet for color-coded results · All dimensions in METERS
A4: ⚙ PARAMETERS — Blue cells are editable inputs
A5: Velocity Factor (VF): | D5: 0.975 | E5: ← Editable. Bare wire in free air ≈ 0.95–1.00. Default 0.975 (typical outdoor wire).
A6: Half-wave formula used: | D6: λ/2 (m) = VF × 150 / f_center(MHz) → λ/4 (m) = λ/2 / 2
A8: 📻 BAND SELECTION — Change 'ACTIVE?' column to YES or NO (dropdown available)
A9: ⚠ Lengths at an INTEGER multiple of λ/2 (very high feedpoint Z) OR at λ/4 multiples (very low feedpoint Z) cause poor UnUn matching — the algorithm AVOIDS both. Wires shorter than λ/4 of the lowest active band are also penalised (scored 0).
A10: Band | B10: f Low (MHz) | C10: f High (MHz) | D10: f Center (MHz) | E10: ACTIVE? | F10: λ/2 (meters) | G10: λ/4 (meters) | H10: Min Wire (meters)
A11: 160m | B11: 1.8 | C11: 2 | D11: =(B11+C11)/2 -> 1.9 | E11: NO | F11: =$D$5*150/D11 -> 76.973684 | G11: =F11/2 -> 38.486842 | H11: =$D$5*75/B11 -> 40.625
A12: 80m | B12: 3.5 | C12: 3.8 | D12: =(B12+C12)/2 -> 3.65 | E12: NO | F12: =$D$5*150/D12 -> 40.068493 | G12: =F12/2 -> 20.034247 | H12: =$D$5*75/B12 -> 20.892857
A13: 60m | B13: 5.3515 | C13: 5.3665 | D13: =(B13+C13)/2 -> 5.359 | E13: NO | F13: =$D$5*150/D13 -> 27.290539 | G13: =F13/2 -> 13.64527 | H13: =$D$5*75/B13 -> 13.664393
A14: 40m | B14: 7 | C14: 7.3 | D14: =(B14+C14)/2 -> 7.15 | E14: NO | F14: =$D$5*150/D14 -> 20.454545 | G14: =F14/2 -> 10.227273 | H14: =$D$5*75/B14 -> 10.446429
A15: 30m | B15: 10.1 | C15: 10.15 | D15: =(B15+C15)/2 -> 10.125 | E15: YES | F15: =$D$5*150/D15 -> 14.444444 | G15: =F15/2 -> 7.2222222 | H15: =$D$5*75/B15 -> 7.240099
A16: 20m | B16: 14 | C16: 14.35 | D16: =(B16+C16)/2 -> 14.175 | E16: YES | F16: =$D$5*150/D16 -> 10.31746 | G16: =F16/2 -> 5.1587302 | H16: =$D$5*75/B16 -> 5.2232143
A17: 17m | B17: 18.068 | C17: 18.168 | D17: =(B17+C17)/2 -> 18.118 | E17: YES | F17: =$D$5*150/D17 -> 8.072083 | G17: =F17/2 -> 4.0360415 | H17: =$D$5*75/B17 -> 4.0472105
A18: 15m | B18: 21 | C18: 21.45 | D18: =(B18+C18)/2 -> 21.225 | E18: YES | F18: =$D$5*150/D18 -> 6.8904594 | G18: =F18/2 -> 3.4452297 | H18: =$D$5*75/B18 -> 3.4821429
A19: 12m | B19: 24.89 | C19: 24.99 | D19: =(B19+C19)/2 -> 24.94 | E19: YES | F19: =$D$5*150/D19 -> 5.8640738 | G19: =F19/2 -> 2.9320369 | H19: =$D$5*75/B19 -> 2.9379269
A20: 10m | B20: 28 | C20: 29.7 | D20: =(B20+C20)/2 -> 28.85 | E20: YES | F20: =$D$5*150/D20 -> 5.0693241 | G20: =F20/2 -> 2.534662 | H20: =$D$5*75/B20 -> 2.6116071
A21: 6m | B21: 50 | C21: 54 | D21: =(B21+C21)/2 -> 52 | E21: NO | F21: =$D$5*150/D21 -> 2.8125 | G21: =F21/2 -> 1.40625 | H21: =$D$5*75/B21 -> 1.4625
A23: Active bands: | C23: =COUNTIF(E11:E21,"YES") -> 6 | D23: Min. wire length needed (m): | F23: =IF(COUNTIF(E11:E21,"YES")=0,"N/A",SUMPRODUCT(MAX((E11:E21="YES")*H11:H21))) -> 7.240099 | G23: ← λ/4 of lowest active band
A25: 🔌 COUNTERPOISE (Ground Reference Wire)
A26: Recommended counterpoise (m): | D26: =IF(COUNTIF(E11:E21,"YES")=0,"N/A",SUMPRODUCT(MAX((E11:E21="YES")*H11:H21))) -> 7.240099 | E26: λ/4 of lowest active band. Multiple radials also effective. Keep counterpoise as straight as possible.
A28: 🏆 TOP 5 RECOMMENDED WIRE LENGTHS (computed from 'Length Sweep' sheet — updates with band selection)
A29: Rank | B29: Wire Length (meters) | C29: Wire Length (cm) | D29: Avoidance Score | E29: Quality Rating | F29: λ/2 check (lowest active band; ok = not integer and not n+0.5) | G29: Counterpoise (m) | H29: Practical Notes
A30: # 1 | B30: =IFERROR(INDEX('Length Sweep'!$A$5:$A$115,MATCH(1,'Length Sweep'!$N$5:$N$115,0)),"-") -> 54 | C30: =IFERROR(B30*100,"-") -> 5400 | D30: =IFERROR(LARGE('Length Sweep'!$M$5:$M$115,1),"-") -> 0.15230769 | E30: =IF(ISNUMBER(D30),IF(D30>=0.2,"★★★ EXCELLENT",IF(D30>=0.12,"★★ GOOD",IF(D30>=0.07,"★ FAIR",IF(D30>=0.025,"⚠ MARGINAL","✗ AVOID")))),"—") -> ★★ GOOD | F30: =IFERROR(TEXT(B30/SUMPRODUCT(MAX((Calculator!$E$11:$E$21="YES")*Calculator!$F$11:$F$21)),"0.00")&" × λ/2 @lowest band","—") -> 3,74 × λ/2 @lowest band | G30: =IF(COUNTIF(E11:E21,"YES")=0,"N/A",SUMPRODUCT(MAX((E11:E21="YES")*H11:H21))) -> 7.240099 | H30: =IF(ISNUMBER(B30),IF(B30<10,"Short – portable use only",IF(B30<18,"Portable / SOTA",IF(B30<30,"Good portable/home",IF(B30<45,"Excellent home station","Long wire – max performance")))),"-") -> Long wire – max performance
A31: # 2 | B31: =IFERROR(INDEX('Length Sweep'!$A$5:$A$115,MATCH(2,'Length Sweep'!$N$5:$N$115,0)),"-") -> 39 | C31: =IFERROR(B31*100,"-") -> 3900 | D31: =IFERROR(LARGE('Length Sweep'!$M$5:$M$115,2),"-") -> 0.15066667 | E31: =IF(ISNUMBER(D31),IF(D31>=0.2,"★★★ EXCELLENT",IF(D31>=0.12,"★★ GOOD",IF(D31>=0.07,"★ FAIR",IF(D31>=0.025,"⚠ MARGINAL","✗ AVOID")))),"—") -> ★★ GOOD | F31: =IFERROR(TEXT(B31/SUMPRODUCT(MAX((Calculator!$E$11:$E$21="YES")*Calculator!$F$11:$F$21)),"0.00")&" × λ/2 @lowest band","—") -> 2,70 × λ/2 @lowest band | G31: =IF(COUNTIF(E11:E21,"YES")=0,"N/A",SUMPRODUCT(MAX((E11:E21="YES")*H11:H21))) -> 7.240099 | H31: =IF(ISNUMBER(B31),IF(B31<10,"Short – portable use only",IF(B31<18,"Portable / SOTA",IF(B31<30,"Good portable/home",IF(B31<45,"Excellent home station","Long wire – max performance")))),"-") -> Excellent home station
A32: # 3 | B32: =IFERROR(INDEX('Length Sweep'!$A$5:$A$115,MATCH(3,'Length Sweep'!$N$5:$N$115,0)),"-") -> 18.5 | C32: =IFERROR(B32*100,"-") -> 1850 | D32: =IFERROR(LARGE('Length Sweep'!$M$5:$M$115,3),"-") -> 0.14940171 | E32: =IF(ISNUMBER(D32),IF(D32>=0.2,"★★★ EXCELLENT",IF(D32>=0.12,"★★ GOOD",IF(D32>=0.07,"★ FAIR",IF(D32>=0.025,"⚠ MARGINAL","✗ AVOID")))),"—") -> ★★ GOOD | F32: =IFERROR(TEXT(B32/SUMPRODUCT(MAX((Calculator!$E$11:$E$21="YES")*Calculator!$F$11:$F$21)),"0.00")&" × λ/2 @lowest band","—") -> 1,28 × λ/2 @lowest band | G32: =IF(COUNTIF(E11:E21,"YES")=0,"N/A",SUMPRODUCT(MAX((E11:E21="YES")*H11:H21))) -> 7.240099 | H32: =IF(ISNUMBER(B32),IF(B32<10,"Short – portable use only",IF(B32<18,"Portable / SOTA",IF(B32<30,"Good portable/home",IF(B32<45,"Excellent home station","Long wire – max performance")))),"-") -> Good portable/home
A33: # 4 | B33: =IFERROR(INDEX('Length Sweep'!$A$5:$A$115,MATCH(4,'Length Sweep'!$N$5:$N$115,0)),"-") -> 19 | C33: =IFERROR(B33*100,"-") -> 1900 | D33: =IFERROR(LARGE('Length Sweep'!$M$5:$M$115,4),"-") -> 0.14620855 | E33: =IF(ISNUMBER(D33),IF(D33>=0.2,"★★★ EXCELLENT",IF(D33>=0.12,"★★ GOOD",IF(D33>=0.07,"★ FAIR",IF(D33>=0.025,"⚠ MARGINAL","✗ AVOID")))),"—") -> ★★ GOOD | F33: =IFERROR(TEXT(B33/SUMPRODUCT(MAX((Calculator!$E$11:$E$21="YES")*Calculator!$F$11:$F$21)),"0.00")&" × λ/2 @lowest band","—") -> 1,32 × λ/2 @lowest band | G33: =IF(COUNTIF(E11:E21,"YES")=0,"N/A",SUMPRODUCT(MAX((E11:E21="YES")*H11:H21))) -> 7.240099 | H33: =IF(ISNUMBER(B33),IF(B33<10,"Short – portable use only",IF(B33<18,"Portable / SOTA",IF(B33<30,"Good portable/home",IF(B33<45,"Excellent home station","Long wire – max performance")))),"-") -> Good portable/home
A34: # 5 | B34: =IFERROR(INDEX('Length Sweep'!$A$5:$A$115,MATCH(5,'Length Sweep'!$N$5:$N$115,0)),"-") -> 59.5 | C34: =IFERROR(B34*100,"-") -> 5950 | D34: =IFERROR(LARGE('Length Sweep'!$M$5:$M$115,5),"-") -> 0.11923077 | E34: =IF(ISNUMBER(D34),IF(D34>=0.2,"★★★ EXCELLENT",IF(D34>=0.12,"★★ GOOD",IF(D34>=0.07,"★ FAIR",IF(D34>=0.025,"⚠ MARGINAL","✗ AVOID")))),"—") -> ★ FAIR | F34: =IFERROR(TEXT(B34/SUMPRODUCT(MAX((Calculator!$E$11:$E$21="YES")*Calculator!$F$11:$F$21)),"0.00")&" × λ/2 @lowest band","—") -> 4,12 × λ/2 @lowest band | G34: =IF(COUNTIF(E11:E21,"YES")=0,"N/A",SUMPRODUCT(MAX((E11:E21="YES")*H11:H21))) -> 7.240099 | H34: =IF(ISNUMBER(B34),IF(B34<10,"Short – portable use only",IF(B34<18,"Portable / SOTA",IF(B34<30,"Good portable/home",IF(B34<45,"Excellent home station","Long wire – max performance")))),"-") -> Long wire – max performance
A35: ℹ Avoidance Score explanation: 0.25 = wire is at maximum distance from ALL resonances (ideal: 3λ/8 or 5λ/8); 0.00 = wire IS resonant (half-wave or quarter-wave, extremely high or low impedance, avoid); Score ≥ 0.20 = excellent; Score ≥ 0.12 = good practice.

Sheet VSWR Calculator
A1: 📡 VSWR Estimator — Long Wire Antenna + 9:1 UnUn
A2: ⚠ Simplified model: Z_wire ≈ 50 × 80^cos²(π·L/λ½) Ω → VSWR = max(Z_wire/450, 450/Z_wire) | Z_min ≈ 50 Ω at λ/4 · Z_max ≈ 4000 Ω at λ/2 · Z_target = 450 Ω at 3λ/8 (9:1 UnUn ideal). Real-world values vary with wire height, soil, and coupling.
A4: Wire Length (m): | C4: 39 | D4: ← Enter wire length (m) above. Top-5 recommended: see Calculator sheet.
A6: Band | B6: Active? | C6: λ/2 (m) | D6: λ/4 (m) | E6: L / λ½ (frac) | F6: Z_wire (Ω, est.) | G6: VSWR (chart data) | H6: VSWR | I6: Quality Assessment
A7: =Calculator!A11 -> 160m | B7: =Calculator!$E$11 -> NO | C7: =ROUND(Calculator!$F$11,2) -> 76.97 | D7: =ROUND(Calculator!$G$11,2) -> 38.49 | E7: =IF(AND(B7="YES",$C$4>=D7),MOD($C$4/C7,1),"—") -> — | F7: =IF(AND(B7="YES",$C$4>=D7),ROUND(50*POWER(80,COS(PI()*MOD($C$4/C7,1))^2),0),"—") -> — | G7: =IF($C$4<D7,NA(),MAX(50*POWER(80,COS(PI()*MOD($C$4/C7,1))^2)/450,450/(50*POWER(80,COS(PI()*MOD($C$4/C7,1))^2)))) -> 8.9825938 | H7: =IF(B7<>"YES","—",IF($C$4<D7,"< λ/4",TEXT(G7,"0.0"))) -> — | I7: =IF(B7<>"YES","Inactive band",IF($C$4<D7,"Wire too short for this band",IF(G7<1.5,"✔ Excellent — no tuner needed",IF(G7<3,"✔ Good — most tuners handle this",IF(G7<6,"⚠ Marginal — tuner required","✗ Poor — high-loss mismatch"))))) -> Inactive band
A8: =Calculator!A12 -> 80m | B8: =Calculator!$E$12 -> NO | C8: =ROUND(Calculator!$F$12,2) -> 40.07 | D8: =ROUND(Calculator!$G$12,2) -> 20.03 | E8: =IF(AND(B8="YES",$C$4>=D8),MOD($C$4/C8,1),"—") -> — | F8: =IF(AND(B8="YES",$C$4>=D8),ROUND(50*POWER(80,COS(PI()*MOD($C$4/C8,1))^2),0),"—") -> — | G8: =IF($C$4<D8,NA(),MAX(50*POWER(80,COS(PI()*MOD($C$4/C8,1))^2)/450,450/(50*POWER(80,COS(PI()*MOD($C$4/C8,1))^2)))) -> 8.6195691 | H8: =IF(B8<>"YES","—",IF($C$4<D8,"< λ/4",TEXT(G8,"0.0"))) -> — | I8: =IF(B8<>"YES","Inactive band",IF($C$4<D8,"Wire too short for this band",IF(G8<1.5,"✔ Excellent — no tuner needed",IF(G8<3,"✔ Good — most tuners handle this",IF(G8<6,"⚠ Marginal — tuner required","✗ Poor — high-loss mismatch"))))) -> Inactive band
A9: =Calculator!A13 -> 60m | B9: =Calculator!$E$13 -> NO | C9: =ROUND(Calculator!$F$13,2) -> 27.29 | D9: =ROUND(Calculator!$G$13,2) -> 13.65 | E9: =IF(AND(B9="YES",$C$4>=D9),MOD($C$4/C9,1),"—") -> — | F9: =IF(AND(B9="YES",$C$4>=D9),ROUND(50*POWER(80,COS(PI()*MOD($C$4/C9,1))^2),0),"—") -> — | G9: =IF($C$4<D9,NA(),MAX(50*POWER(80,COS(PI()*MOD($C$4/C9,1))^2)/450,450/(50*POWER(80,COS(PI()*MOD($C$4/C9,1))^2)))) -> 7.2671351 | H9: =IF(B9<>"YES","—",IF($C$4<D9,"< λ/4",TEXT(G9,"0.0"))) -> — | I9: =IF(B9<>"YES","Inactive band",IF($C$4<D9,"Wire too short for this band",IF(G9<1.5,"✔ Excellent — no tuner needed",IF(G9<3,"✔ Good — most tuners handle this",IF(G9<6,"⚠ Marginal — tuner required","✗ Poor — high-loss mismatch"))))) -> Inactive band
A10: =Calculator!A14 -> 40m | B10: =Calculator!$E$14 -> NO | C10: =ROUND(Calculator!$F$14,2) -> 20.45 | D10: =ROUND(Calculator!$G$14,2) -> 10.23 | E10: =IF(AND(B10="YES",$C$4>=D10),MOD($C$4/C10,1),"—") -> — | F10: =IF(AND(B10="YES",$C$4>=D10),ROUND(50*POWER(80,COS(PI()*MOD($C$4/C10,1))^2),0),"—") -> — | G10: =IF($C$4<D10,NA(),MAX(50*POWER(80,COS(PI()*MOD($C$4/C10,1))^2)/450,450/(50*POWER(80,COS(PI()*MOD($C$4/C10,1))^2)))) -> 6.1839202 | H10: =IF(B10<>"YES","—",IF($C$4<D10,"< λ/4",TEXT(G10,"0.0"))) -> — | I10: =IF(B10<>"YES","Inactive band",IF($C$4<D10,"Wire too short for this band",IF(G10<1.5,"✔ Excellent — no tuner needed",IF(G10<3,"✔ Good — most tuners handle this",IF(G10<6,"⚠ Marginal — tuner required","✗ Poor — high-loss mismatch"))))) -> Inactive band
A11: =Calculator!A15 -> 30m | B11: =Calculator!$E$15 -> YES | C11: =ROUND(Calculator!$F$15,2) -> 14.44 | D11: =ROUND(Calculator!$G$15,2) -> 7.22 | E11: =IF(AND(B11="YES",$C$4>=D11),MOD($C$4/C11,1),"—") -> 0.70083102 | F11: =IF(AND(B11="YES",$C$4>=D11),ROUND(50*POWER(80,COS(PI()*MOD($C$4/C11,1))^2),0),"—") -> 230 | G11: =IF($C$4<D11,NA(),MAX(50*POWER(80,COS(PI()*MOD($C$4/C11,1))^2)/450,450/(50*POWER(80,COS(PI()*MOD($C$4/C11,1))^2)))) -> 1.9588979 | H11: =IF(B11<>"YES","—",IF($C$4<D11,"< λ/4",TEXT(G11,"0.0"))) -> 2.0 | I11: =IF(B11<>"YES","Inactive band",IF($C$4<D11,"Wire too short for this band",IF(G11<1.5,"✔ Excellent — no tuner needed",IF(G11<3,"✔ Good — most tuners handle this",IF(G11<6,"⚠ Marginal — tuner required","✗ Poor — high-loss mismatch"))))) -> ✔ Good — most tuners handle this
A12: =Calculator!A16 -> 20m | B12: =Calculator!$E$16 -> YES | C12: =ROUND(Calculator!$F$16,2) -> 10.32 | D12: =ROUND(Calculator!$G$16,2) -> 5.16 | E12: =IF(AND(B12="YES",$C$4>=D12),MOD($C$4/C12,1),"—") -> 0.77906977 | F12: =IF(AND(B12="YES",$C$4>=D12),ROUND(50*POWER(80,COS(PI()*MOD($C$4/C12,1))^2),0),"—") -> 666 | G12: =IF($C$4<D12,NA(),MAX(50*POWER(80,COS(PI()*MOD($C$4/C12,1))^2)/450,450/(50*POWER(80,COS(PI()*MOD($C$4/C12,1))^2)))) -> 1.4795789 | H12: =IF(B12<>"YES","—",IF($C$4<D12,"< λ/4",TEXT(G12,"0.0"))) -> 1.5 | I12: =IF(B12<>"YES","Inactive band",IF($C$4<D12,"Wire too short for this band",IF(G12<1.5,"✔ Excellent — no tuner needed",IF(G12<3,"✔ Good — most tuners handle this",IF(G12<6,"⚠ Marginal — tuner required","✗ Poor — high-loss mismatch"))))) -> ✔ Excellent — no tuner needed
A13: =Calculator!A17 -> 17m | B13: =Calculator!$E$17 -> YES | C13: =ROUND(Calculator!$F$17,2) -> 8.07 | D13: =ROUND(Calculator!$G$17,2) -> 4.04 | E13: =IF(AND(B13="YES",$C$4>=D13),MOD($C$4/C13,1),"—") -> 0.83271375 | F13: =IF(AND(B13="YES",$C$4>=D13),ROUND(50*POWER(80,COS(PI()*MOD($C$4/C13,1))^2),0),"—") -> 1328 | G13: =IF($C$4<D13,NA(),MAX(50*POWER(80,COS(PI()*MOD($C$4/C13,1))^2)/450,450/(50*POWER(80,COS(PI()*MOD($C$4/C13,1))^2)))) -> 2.9502809 | H13: =IF(B13<>"YES","—",IF($C$4<D13,"< λ/4",TEXT(G13,"0.0"))) -> 3.0 | I13: =IF(B13<>"YES","Inactive band",IF($C$4<D13,"Wire too short for this band",IF(G13<1.5,"✔ Excellent — no tuner needed",IF(G13<3,"✔ Good — most tuners handle this",IF(G13<6,"⚠ Marginal — tuner required","✗ Poor — high-loss mismatch"))))) -> ✔ Good — most tuners handle this
A14: =Calculator!A18 -> 15m | B14: =Calculator!$E$18 -> YES | C14: =ROUND(Calculator!$F$18,2) -> 6.89 | D14: =ROUND(Calculator!$G$18,2) -> 3.45 | E14: =IF(AND(B14="YES",$C$4>=D14),MOD($C$4/C14,1),"—") -> 0.66037736 | F14: =IF(AND(B14="YES",$C$4>=D14),ROUND(50*POWER(80,COS(PI()*MOD($C$4/C14,1))^2),0),"—") -> 139 | G14: =IF($C$4<D14,NA(),MAX(50*POWER(80,COS(PI()*MOD($C$4/C14,1))^2)/450,450/(50*POWER(80,COS(PI()*MOD($C$4/C14,1))^2)))) -> 3.2408168 | H14: =IF(B14<>"YES","—",IF($C$4<D14,"< λ/4",TEXT(G14,"0.0"))) -> 3.2 | I14: =IF(B14<>"YES","Inactive band",IF($C$4<D14,"Wire too short for this band",IF(G14<1.5,"✔ Excellent — no tuner needed",IF(G14<3,"✔ Good — most tuners handle this",IF(G14<6,"⚠ Marginal — tuner required","✗ Poor — high-loss mismatch"))))) -> ⚠ Marginal — tuner required
A15: =Calculator!A19 -> 12m | B15: =Calculator!$E$19 -> YES | C15: =ROUND(Calculator!$F$19,2) -> 5.86 | D15: =ROUND(Calculator!$G$19,2) -> 2.93 | E15: =IF(AND(B15="YES",$C$4>=D15),MOD($C$4/C15,1),"—") -> 0.6552901 | F15: =IF(AND(B15="YES",$C$4>=D15),ROUND(50*POWER(80,COS(PI()*MOD($C$4/C15,1))^2),0),"—") -> 131 | G15: =IF($C$4<D15,NA(),MAX(50*POWER(80,COS(PI()*MOD($C$4/C15,1))^2)/450,450/(50*POWER(80,COS(PI()*MOD($C$4/C15,1))^2)))) -> 3.4364476 | H15: =IF(B15<>"YES","—",IF($C$4<D15,"< λ/4",TEXT(G15,"0.0"))) -> 03 | I15: =IF(B15<>"YES","Inactive band",IF($C$4<D15,"Wire too short for this band",IF(G15<1.5,"✔ Excellent — no tuner needed",IF(G15<3,"✔ Good — most tuners handle this",IF(G15<6,"⚠ Marginal — tuner required","✗ Poor — high-loss mismatch"))))) -> ⚠ Marginal — tuner required
A16: =Calculator!A20 -> 10m | B16: =Calculator!$E$20 -> YES | C16: =ROUND(Calculator!$F$20,2) -> 5.07 | D16: =ROUND(Calculator!$G$20,2) -> 2.53 | E16: =IF(AND(B16="YES",$C$4>=D16),MOD($C$4/C16,1),"—") -> 0.69230769 | F16: =IF(AND(B16="YES",$C$4>=D16),ROUND(50*POWER(80,COS(PI()*MOD($C$4/C16,1))^2),0),"—") -> 206 | G16: =IF($C$4<D16,NA(),MAX(50*POWER(80,COS(PI()*MOD($C$4/C16,1))^2)/450,450/(50*POWER(80,COS(PI()*MOD($C$4/C16,1))^2)))) -> 2.1883663 | H16: =IF(B16<>"YES","—",IF($C$4<D16,"< λ/4",TEXT(G16,"0.0"))) -> 2.2 | I16: =IF(B16<>"YES","Inactive band",IF($C$4<D16,"Wire too short for this band",IF(G16<1.5,"✔ Excellent — no tuner needed",IF(G16<3,"✔ Good — most tuners handle this",IF(G16<6,"⚠ Marginal — tuner required","✗ Poor — high-loss mismatch"))))) -> ✔ Good — most tuners handle this
A17: =Calculator!A21 -> 6m | B17: =Calculator!$E$21 -> NO | C17: =ROUND(Calculator!$F$21,2) -> 2.81 | D17: =ROUND(Calculator!$G$21,2) -> 1.41 | E17: =IF(AND(B17="YES",$C$4>=D17),MOD($C$4/C17,1),"—") -> — | F17: =IF(AND(B17="YES",$C$4>=D17),ROUND(50*POWER(80,COS(PI()*MOD($C$4/C17,1))^2),0),"—") -> — | G17: =IF($C$4<D17,NA(),MAX(50*POWER(80,COS(PI()*MOD($C$4/C17,1))^2)/450,450/(50*POWER(80,COS(PI()*MOD($C$4/C17,1))^2)))) -> 4.862473 | H17: =IF(B17<>"YES","—",IF($C$4<D17,"< λ/4",TEXT(G17,"0.0"))) -> — | I17: =IF(B17<>"YES","Inactive band",IF($C$4<D17,"Wire too short for this band",IF(G17<1.5,"✔ Excellent — no tuner needed",IF(G17<3,"✔ Good — most tuners handle this",IF(G17<6,"⚠ Marginal — tuner required","✗ Poor — high-loss mismatch"))))) -> Inactive band
A19: VSWR guide: | C19: < 1.5: Excellent | D19: 1.5–3.0: Good (tuner helpful) | E19: 3.0–6.0: Marginal (tuner needed) | F19: > 6.0: Poor (high-loss mismatch)
A21: 📊 Chart below — Dashed reference thresholds: VSWR 1.5 = excellent boundary · VSWR 3.0 = tuner boundary · Bars absent = inactive band or wire too short for that band

Sheet Length Sweep
A1: 📊 Wire Length Sweep 5.0 – 60.0 m (step 0.5 m) — Resonance Avoidance Score · GREEN rows = recommended
A2: Score = MIN fraction-away-from BOTH half-wave AND quarter-wave resonances across ALL active bands. 0.25 = perfect (mid-gap between λ/4 and λ/2), 0.00 = on resonance. Inactive bands show 1.00 (not counted). Formula: =MIN(MIN(MOD(L/λ₂,1), 1−MOD(L/λ₂,1)), |MOD(L/λ₂,1)−0.5|) per active band. ⚠ Both λ/2 (very high Z, >2000Ω) AND λ/4 (very low Z, ~50Ω→5.5Ω after UnUn) are penalized.
A3: ⚠ Change band ACTIVE? selection on the 'Calculator' sheet — this table updates automatically!
A4: Wire Length (m) | B4: 160m score | C4: 80m score | D4: 60m score | E4: 40m score | F4: 30m score | G4: 20m score | H4: 17m score | I4: 15m score | J4: 12m score | K4: 10m score | L4: 6m score | M4: OVERALL Score | N4: Rank | O4: Quality Rating
A5: 5 | B5: =IF(Calculator!$E$11="YES",IF(A5<Calculator!$G$11,0,MIN(MIN(MOD(A5/Calculator!$F$11,1),1-MOD(A5/Calculator!$F$11,1)),ABS(MOD(A5/Calculator!$F$11,1)-0.5))),1) -> 1 | C5: =IF(Calculator!$E$12="YES",IF(A5<Calculator!$G$12,0,MIN(MIN(MOD(A5/Calculator!$F$12,1),1-MOD(A5/Calculator!$F$12,1)),ABS(MOD(A5/Calculator!$F$12,1)-0.5))),1) -> 1 | D5: =IF(Calculator!$E$13="YES",IF(A5<Calculator!$G$13,0,MIN(MIN(MOD(A5/Calculator!$F$13,1),1-MOD(A5/Calculator!$F$13,1)),ABS(MOD(A5/Calculator!$F$13,1)-0.5))),1) -> 1 | E5: =IF(Calculator!$E$14="YES",IF(A5<Calculator!$G$14,0,MIN(MIN(MOD(A5/Calculator!$F$14,1),1-MOD(A5/Calculator!$F$14,1)),ABS(MOD(A5/Calculator!$F$14,1)-0.5))),1) -> 1 | F5: =IF(Calculator!$E$15="YES",IF(A5<Calculator!$G$15,0,MIN(MIN(MOD(A5/Calculator!$F$15,1),1-MOD(A5/Calculator!$F$15,1)),ABS(MOD(A5/Calculator!$F$15,1)-0.5))),1) -> 0 | G5: =IF(Calculator!$E$16="YES",IF(A5<Calculator!$G$16,0,MIN(MIN(MOD(A5/Calculator!$F$16,1),1-MOD(A5/Calculator!$F$16,1)),ABS(MOD(A5/Calculator!$F$16,1)-0.5))),1) -> 0 | H5: =IF(Calculator!$E$17="YES",IF(A5<Calculator!$G$17,0,MIN(MIN(MOD(A5/Calculator!$F$17,1),1-MOD(A5/Calculator!$F$17,1)),ABS(MOD(A5/Calculator!$F$17,1)-0.5))),1) -> 0.1194188 | I5: =IF(Calculator!$E$18="YES",IF(A5<Calculator!$G$18,0,MIN(MIN(MOD(A5/Calculator!$F$18,1),1-MOD(A5/Calculator!$F$18,1)),ABS(MOD(A5/Calculator!$F$18,1)-0.5))),1) -> 0.22564103 | J5: =IF(Calculator!$E$19="YES",IF(A5<Calculator!$G$19,0,MIN(MIN(MOD(A5/Calculator!$F$19,1),1-MOD(A5/Calculator!$F$19,1)),ABS(MOD(A5/Calculator!$F$19,1)-0.5))),1) -> 0.14735043 | K5: =IF(Calculator!$E$20="YES",IF(A5<Calculator!$G$20,0,MIN(MIN(MOD(A5/Calculator!$F$20,1),1-MOD(A5/Calculator!$F$20,1)),ABS(MOD(A5/Calculator!$F$20,1)-0.5))),1) -> 0.013675214 | L5: =IF(Calculator!$E$21="YES",IF(A5<Calculator!$G$21,0,MIN(MIN(MOD(A5/Calculator!$F$21,1),1-MOD(A5/Calculator!$F$21,1)),ABS(MOD(A5/Calculator!$F$21,1)-0.5))),1) -> 1 | M5: =MIN(B5:L5) -> 0 | N5: =SUMPRODUCT(($M$5:$M$115>M5)*1)+SUMPRODUCT(($M$5:$M$115=M5)*(ROW($M$5:$M$115)<ROW(M5)))+1 -> 107 | O5: =IF(M5>=0.2,"★★★ EXCELLENT",IF(M5>=0.12,"★★ GOOD",IF(M5>=0.07,"★ FAIR",IF(M5>=0.025,"⚠ MARGINAL","✗ AVOID")))) -> ✗ AVOID
A6: 5.5 | B6: =IF(Calculator!$E$11="YES",IF(A6<Calculator!$G$11,0,MIN(MIN(MOD(A6/Calculator!$F$11,1),1-MOD(A6/Calculator!$F$11,1)),ABS(MOD(A6/Calculator!$F$11,1)-0.5))),1) -> 1 | C6: =IF(Calculator!$E$12="YES",IF(A6<Calculator!$G$12,0,MIN(MIN(MOD(A6/Calculator!$F$12,1),1-MOD(A6/Calculator!$F$12,1)),ABS(MOD(A6/Calculator!$F$12,1)-0.5))),1) -> 1 | D6: =IF(Calculator!$E$13="YES",IF(A6<Calculator!$G$13,0,MIN(MIN(MOD(A6/Calculator!$F$13,1),1-MOD(A6/Calculator!$F$13,1)),ABS(MOD(A6/Calculator!$F$13,1)-0.5))),1) -> 1 | E6: =IF(Calculator!$E$14="YES",IF(A6<Calculator!$G$14,0,MIN(MIN(MOD(A6/Calculator!$F$14,1),1-MOD(A6/Calculator!$F$14,1)),ABS(MOD(A6/Calculator!$F$14,1)-0.5))),1) -> 1 | F6: =IF(Calculator!$E$15="YES",IF(A6<Calculator!$G$15,0,MIN(MIN(MOD(A6/Calculator!$F$15,1),1-MOD(A6/Calculator!$F$15,1)),ABS(MOD(A6/Calculator!$F$15,1)-0.5))),1) -> 0 | G6: =IF(Calculator!$E$16="YES",IF(A6<Calculator!$G$16,0,MIN(MIN(MOD(A6/Calculator!$F$16,1),1-MOD(A6/Calculator!$F$16,1)),ABS(MOD(A6/Calculator!$F$16,1)-0.5))),1) -> 0.033076923 | H6: =IF(Calculator!$E$17="YES",IF(A6<Calculator!$G$17,0,MIN(MIN(MOD(A6/Calculator!$F$17,1),1-MOD(A6/Calculator!$F$17,1)),ABS(MOD(A6/Calculator!$F$17,1)-0.5))),1) -> 0.18136068 | I6: =IF(Calculator!$E$18="YES",IF(A6<Calculator!$G$18,0,MIN(MIN(MOD(A6/Calculator!$F$18,1),1-MOD(A6/Calculator!$F$18,1)),ABS(MOD(A6/Calculator!$F$18,1)-0.5))),1) -> 0.20179487 | J6: =IF(Calculator!$E$19="YES",IF(A6<Calculator!$G$19,0,MIN(MIN(MOD(A6/Calculator!$F$19,1),1-MOD(A6/Calculator!$F$19,1)),ABS(MOD(A6/Calculator!$F$19,1)-0.5))),1) -> 0.06208547 | K6: =IF(Calculator!$E$20="YES",IF(A6<Calculator!$G$20,0,MIN(MIN(MOD(A6/Calculator!$F$20,1),1-MOD(A6/Calculator!$F$20,1)),ABS(MOD(A6/Calculator!$F$20,1)-0.5))),1) -> 0.084957265 | L6: =IF(Calculator!$E$21="YES",IF(A6<Calculator!$G$21,0,MIN(MIN(MOD(A6/Calculator!$F$21,1),1-MOD(A6/Calculator!$F$21,1)),ABS(MOD(A6/Calculator!$F$21,1)-0.5))),1) -> 1 | M6: =MIN(B6:L6) -> 0 | N6: =SUMPRODUCT(($M$5:$M$115>M6)*1)+SUMPRODUCT(($M$5:$M$115=M6)*(ROW($M$5:$M$115)<ROW(M6)))+1 -> 108 | O6: =IF(M6>=0.2,"★★★ EXCELLENT",IF(M6>=0.12,"★★ GOOD",IF(M6>=0.07,"★ FAIR",IF(M6>=0.025,"⚠ MARGINAL","✗ AVOID")))) -> ✗ AVOID
A7: 6 | B7: =IF(Calculator!$E$11="YES",IF(A7<Calculator!$G$11,0,MIN(MIN(MOD(A7/Calculator!$F$11,1),1-MOD(A7/Calculator!$F$11,1)),ABS(MOD(A7/Calculator!$F$11,1)-0.5))),1) -> 1 | C7: =IF(Calculator!$E$12="YES",IF(A7<Calculator!$G$12,0,MIN(MIN(MOD(A7/Calculator!$F$12,1),1-MOD(A7/Calculator!$F$12,1)),ABS(MOD(A7/Calculator!$F$12,1)-0.5))),1) -> 1 | D7: =IF(Calculator!$E$13="YES",IF(A7<Calculator!$G$13,0,MIN(MIN(MOD(A7/Calculator!$F$13,1),1-MOD(A7/Calculator!$F$13,1)),ABS(MOD(A7/Calculator!$F$13,1)-0.5))),1) -> 1 | E7: =IF(Calculator!$E$14="YES",IF(A7<Calculator!$G$14,0,MIN(MIN(MOD(A7/Calculator!$F$14,1),1-MOD(A7/Calculator!$F$14,1)),ABS(MOD(A7/Calculator!$F$14,1)-0.5))),1) -> 1 | F7: =IF(Calculator!$E$15="YES",IF(A7<Calculator!$G$15,0,MIN(MIN(MOD(A7/Calculator!$F$15,1),1-MOD(A7/Calculator!$F$15,1)),ABS(MOD(A7/Calculator!$F$15,1)-0.5))),1) -> 0 | G7: =IF(Calculator!$E$16="YES",IF(A7<Calculator!$G$16,0,MIN(MIN(MOD(A7/Calculator!$F$16,1),1-MOD(A7/Calculator!$F$16,1)),ABS(MOD(A7/Calculator!$F$16,1)-0.5))),1) -> 0.081538462 | H7: =IF(Calculator!$E$17="YES",IF(A7<Calculator!$G$17,0,MIN(MIN(MOD(A7/Calculator!$F$17,1),1-MOD(A7/Calculator!$F$17,1)),ABS(MOD(A7/Calculator!$F$17,1)-0.5))),1) -> 0.24330256 | I7: =IF(Calculator!$E$18="YES",IF(A7<Calculator!$G$18,0,MIN(MIN(MOD(A7/Calculator!$F$18,1),1-MOD(A7/Calculator!$F$18,1)),ABS(MOD(A7/Calculator!$F$18,1)-0.5))),1) -> 0.12923077 | J7: =IF(Calculator!$E$19="YES",IF(A7<Calculator!$G$19,0,MIN(MIN(MOD(A7/Calculator!$F$19,1),1-MOD(A7/Calculator!$F$19,1)),ABS(MOD(A7/Calculator!$F$19,1)-0.5))),1) -> 0.023179487 | K7: =IF(Calculator!$E$20="YES",IF(A7<Calculator!$G$20,0,MIN(MIN(MOD(A7/Calculator!$F$20,1),1-MOD(A7/Calculator!$F$20,1)),ABS(MOD(A7/Calculator!$F$20,1)-0.5))),1) -> 0.18358974 | L7: =IF(Calculator!$E$21="YES",IF(A7<Calculator!$G$21,0,MIN(MIN(MOD(A7/Calculator!$F$21,1),1-MOD(A7/Calculator!$F$21,1)),ABS(MOD(A7/Calculator!$F$21,1)-0.5))),1) -> 1 | M7: =MIN(B7:L7) -> 0 | N7: =SUMPRODUCT(($M$5:$M$115>M7)*1)+SUMPRODUCT(($M$5:$M$115=M7)*(ROW($M$5:$M$115)<ROW(M7)))+1 -> 109 | O7: =IF(M7>=0.2,"★★★ EXCELLENT",IF(M7>=0.12,"★★ GOOD",IF(M7>=0.07,"★ FAIR",IF(M7>=0.025,"⚠ MARGINAL","✗ AVOID")))) -> ✗ AVOID
A8: 6.5 | B8: =IF(Calculator!$E$11="YES",IF(A8<Calculator!$G$11,0,MIN(MIN(MOD(A8/Calculator!$F$11,1),1-MOD(A8/Calculator!$F$11,1)),ABS(MOD(A8/Calculator!$F$11,1)-0.5))),1) -> 1 | C8: =IF(Calculator!$E$12="YES",IF(A8<Calculator!$G$12,0,MIN(MIN(MOD(A8/Calculator!$F$12,1),1-MOD(A8/Calculator!$F$12,1)),ABS(MOD(A8/Calculator!$F$12,1)-0.5))),1) -> 1 | D8: =IF(Calculator!$E$13="YES",IF(A8<Calculator!$G$13,0,MIN(MIN(MOD(A8/Calculator!$F$13,1),1-MOD(A8/Calculator!$F$13,1)),ABS(MOD(A8/Calculator!$F$13,1)-0.5))),1) -> 1 | E8: =IF(Calculator!$E$14="YES",IF(A8<Calculator!$G$14,0,MIN(MIN(MOD(A8/Calculator!$F$14,1),1-MOD(A8/Calculator!$F$14,1)),ABS(MOD(A8/Calculator!$F$14,1)-0.5))),1) -> 1 | F8: =IF(Calculator!$E$15="YES",IF(A8<Calculator!$G$15,0,MIN(MIN(MOD(A8/Calculator!$F$15,1),1-MOD(A8/Calculator!$F$15,1)),ABS(MOD(A8/Calculator!$F$15,1)-0.5))),1) -> 0 | G8: =IF(Calculator!$E$16="YES",IF(A8<Calculator!$G$16,0,MIN(MIN(MOD(A8/Calculator!$F$16,1),1-MOD(A8/Calculator!$F$16,1)),ABS(MOD(A8/Calculator!$F$16,1)-0.5))),1) -> 0.13 | H8: =IF(Calculator!$E$17="YES",IF(A8<Calculator!$G$17,0,MIN(MIN(MOD(A8/Calculator!$F$17,1),1-MOD(A8/Calculator!$F$17,1)),ABS(MOD(A8/Calculator!$F$17,1)-0.5))),1) -> 0.19475556 | I8: =IF(Calculator!$E$18="YES",IF(A8<Calculator!$G$18,0,MIN(MIN(MOD(A8/Calculator!$F$18,1),1-MOD(A8/Calculator!$F$18,1)),ABS(MOD(A8/Calculator!$F$18,1)-0.5))),1) -> 0.056666667 | J8: =IF(Calculator!$E$19="YES",IF(A8<Calculator!$G$19,0,MIN(MIN(MOD(A8/Calculator!$F$19,1),1-MOD(A8/Calculator!$F$19,1)),ABS(MOD(A8/Calculator!$F$19,1)-0.5))),1) -> 0.10844444 | K8: =IF(Calculator!$E$20="YES",IF(A8<Calculator!$G$20,0,MIN(MIN(MOD(A8/Calculator!$F$20,1),1-MOD(A8/Calculator!$F$20,1)),ABS(MOD(A8/Calculator!$F$20,1)-0.5))),1) -> 0.21777778 | L8: =IF(Calculator!$E$21="YES",IF(A8<Calculator!$G$21,0,MIN(MIN(MOD(A8/Calculator!$F$21,1),1-MOD(A8/Calculator!$F$21,1)),ABS(MOD(A8/Calculator!$F$21,1)-0.5))),1) -> 1 | M8: =MIN(B8:L8) -> 0 | N8: =SUMPRODUCT(($M$5:$M$115>M8)*1)+SUMPRODUCT(($M$5:$M$115=M8)*(ROW($M$5:$M$115)<ROW(M8)))+1 -> 110 | O8: =IF(M8>=0.2,"★★★ EXCELLENT",IF(M8>=0.12,"★★ GOOD",IF(M8>=0.07,"★ FAIR",IF(M8>=0.025,"⚠ MARGINAL","✗ AVOID")))) -> ✗ AVOID
A9: 7 | B9: =IF(Calculator!$E$11="YES",IF(A9<Calculator!$G$11,0,MIN(MIN(MOD(A9/Calculator!$F$11,1),1-MOD(A9/Calculator!$F$11,1)),ABS(MOD(A9/Calculator!$F$11,1)-0.5))),1) -> 1 | C9: =IF(Calculator!$E$12="YES",IF(A9<Calculator!$G$12,0,MIN(MIN(MOD(A9/Calculator!$F$12,1),1-MOD(A9/Calculator!$F$12,1)),ABS(MOD(A9/Calculator!$F$12,1)-0.5))),1) -> 1 | D9: =IF(Calculator!$E$13="YES",IF(A9<Calculator!$G$13,0,MIN(MIN(MOD(A9/Calculator!$F$13,1),1-MOD(A9/Calculator!$F$13,1)),ABS(MOD(A9/Calculator!$F$13,1)-0.5))),1) -> 1 | E9: =IF(Calculator!$E$14="YES",IF(A9<Calculator!$G$14,0,MIN(MIN(MOD(A9/Calculator!$F$14,1),1-MOD(A9/Calculator!$F$14,1)),ABS(MOD(A9/Calculator!$F$14,1)-0.5))),1) -> 1 | F9: =IF(Calculator!$E$15="YES",IF(A9<Calculator!$G$15,0,MIN(MIN(MOD(A9/Calculator!$F$15,1),1-MOD(A9/Calculator!$F$15,1)),ABS(MOD(A9/Calculator!$F$15,1)-0.5))),1) -> 0 | G9: =IF(Calculator!$E$16="YES",IF(A9<Calculator!$G$16,0,MIN(MIN(MOD(A9/Calculator!$F$16,1),1-MOD(A9/Calculator!$F$16,1)),ABS(MOD(A9/Calculator!$F$16,1)-0.5))),1) -> 0.17846154 | H9: =IF(Calculator!$E$17="YES",IF(A9<Calculator!$G$17,0,MIN(MIN(MOD(A9/Calculator!$F$17,1),1-MOD(A9/Calculator!$F$17,1)),ABS(MOD(A9/Calculator!$F$17,1)-0.5))),1) -> 0.13281368 | I9: =IF(Calculator!$E$18="YES",IF(A9<Calculator!$G$18,0,MIN(MIN(MOD(A9/Calculator!$F$18,1),1-MOD(A9/Calculator!$F$18,1)),ABS(MOD(A9/Calculator!$F$18,1)-0.5))),1) -> 0.015897436 | J9: =IF(Calculator!$E$19="YES",IF(A9<Calculator!$G$19,0,MIN(MIN(MOD(A9/Calculator!$F$19,1),1-MOD(A9/Calculator!$F$19,1)),ABS(MOD(A9/Calculator!$F$19,1)-0.5))),1) -> 0.1937094 | K9: =IF(Calculator!$E$20="YES",IF(A9<Calculator!$G$20,0,MIN(MIN(MOD(A9/Calculator!$F$20,1),1-MOD(A9/Calculator!$F$20,1)),ABS(MOD(A9/Calculator!$F$20,1)-0.5))),1) -> 0.1191453 | L9: =IF(Calculator!$E$21="YES",IF(A9<Calculator!$G$21,0,MIN(MIN(MOD(A9/Calculator!$F$21,1),1-MOD(A9/Calculator!$F$21,1)),ABS(MOD(A9/Calculator!$F$21,1)-0.5))),1) -> 1 | M9: =MIN(B9:L9) -> 0 | N9: =SUMPRODUCT(($M$5:$M$115>M9)*1)+SUMPRODUCT(($M$5:$M$115=M9)*(ROW($M$5:$M$115)<ROW(M9)))+1 -> 111 | O9: =IF(M9>=0.2,"★★★ EXCELLENT",IF(M9>=0.12,"★★ GOOD",IF(M9>=0.07,"★ FAIR",IF(M9>=0.025,"⚠ MARGINAL","✗ AVOID")))) -> ✗ AVOID
A10: 7.5 | B10: =IF(Calculator!$E$11="YES",IF(A10<Calculator!$G$11,0,MIN(MIN(MOD(A10/Calculator!$F$11,1),1-MOD(A10/Calculator!$F$11,1)),ABS(MOD(A10/Calculator!$F$11,1)-0.5))),1) -> 1 | C10: =IF(Calculator!$E$12="YES",IF(A10<Calculator!$G$12,0,MIN(MIN(MOD(A10/Calculator!$F$12,1),1-MOD(A10/Calculator!$F$12,1)),ABS(MOD(A10/Calculator!$F$12,1)-0.5))),1) -> 1 | D10: =IF(Calculator!$E$13="YES",IF(A10<Calculator!$G$13,0,MIN(MIN(MOD(A10/Calculator!$F$13,1),1-MOD(A10/Calculator!$F$13,1)),ABS(MOD(A10/Calculator!$F$13,1)-0.5))),1) -> 1 | E10: =IF(Calculator!$E$14="YES",IF(A10<Calculator!$G$14,0,MIN(MIN(MOD(A10/Calculator!$F$14,1),1-MOD(A10/Calculator!$F$14,1)),ABS(MOD(A10/Calculator!$F$14,1)-0.5))),1) -> 1 | F10: =IF(Calculator!$E$15="YES",IF(A10<Calculator!$G$15,0,MIN(MIN(MOD(A10/Calculator!$F$15,1),1-MOD(A10/Calculator!$F$15,1)),ABS(MOD(A10/Calculator!$F$15,1)-0.5))),1) -> 0.019230769 | G10: =IF(Calculator!$E$16="YES",IF(A10<Calculator!$G$16,0,MIN(MIN(MOD(A10/Calculator!$F$16,1),1-MOD(A10/Calculator!$F$16,1)),ABS(MOD(A10/Calculator!$F$16,1)-0.5))),1) -> 0.22692308 | H10: =IF(Calculator!$E$17="YES",IF(A10<Calculator!$G$17,0,MIN(MIN(MOD(A10/Calculator!$F$17,1),1-MOD(A10/Calculator!$F$17,1)),ABS(MOD(A10/Calculator!$F$17,1)-0.5))),1) -> 0.070871795 | I10: =IF(Calculator!$E$18="YES",IF(A10<Calculator!$G$18,0,MIN(MIN(MOD(A10/Calculator!$F$18,1),1-MOD(A10/Calculator!$F$18,1)),ABS(MOD(A10/Calculator!$F$18,1)-0.5))),1) -> 0.088461538 | J10: =IF(Calculator!$E$19="YES",IF(A10<Calculator!$G$19,0,MIN(MIN(MOD(A10/Calculator!$F$19,1),1-MOD(A10/Calculator!$F$19,1)),ABS(MOD(A10/Calculator!$F$19,1)-0.5))),1) -> 0.22102564 | K10: =IF(Calculator!$E$20="YES",IF(A10<Calculator!$G$20,0,MIN(MIN(MOD(A10/Calculator!$F$20,1),1-MOD(A10/Calculator!$F$20,1)),ABS(MOD(A10/Calculator!$F$20,1)-0.5))),1) -> 0.020512821 | L10: =IF(Calculator!$E$21="YES",IF(A10<Calculator!$G$21,0,MIN(MIN(MOD(A10/Calculator!$F$21,1),1-MOD(A10/Calculator!$F$21,1)),ABS(MOD(A10/Calculator!$F$21,1)-0.5))),1) -> 1 | M10: =MIN(B10:L10) -> 0.019230769 | N10: =SUMPRODUCT(($M$5:$M$115>M10)*1)+SUMPRODUCT(($M$5:$M$115=M10)*(ROW($M$5:$M$115)<ROW(M10)))+1 -> 68 | O10: =IF(M10>=0.2,"★★★ EXCELLENT",IF(M10>=0.12,"★★ GOOD",IF(M10>=0.07,"★ FAIR",IF(M10>=0.025,"⚠ MARGINAL","✗ AVOID")))) -> ✗ AVOID
A11: 8 | B11: =IF(Calculator!$E$11="YES",IF(A11<Calculator!$G$11,0,MIN(MIN(MOD(A11/Calculator!$F$11,1),1-MOD(A11/Calculator!$F$11,1)),ABS(MOD(A11/Calculator!$F$11,1)-0.5))),1) -> 1 | C11: =IF(Calculator!$E$12="YES",IF(A11<Calculator!$G$12,0,MIN(MIN(MOD(A11/Calculator!$F$12,1),1-MOD(A11/Calculator!$F$12,1)),ABS(MOD(A11/Calculator!$F$12,1)-0.5))),1) -> 1 | D11: =IF(Calculator!$E$13="YES",IF(A11<Calculator!$G$13,0,MIN(MIN(MOD(A11/Calculator!$F$13,1),1-MOD(A11/Calculator!$F$13,1)),ABS(MOD(A11/Calculator!$F$13,1)-0.5))),1) -> 1 | E11: =IF(Calculator!$E$14="YES",IF(A11<Calculator!$G$14,0,MIN(MIN(MOD(A11/Calculator!$F$14,1),1-MOD(A11/Calculator!$F$14,1)),ABS(MOD(A11/Calculator!$F$14,1)-0.5))),1) -> 1 | F11: =IF(Calculator!$E$15="YES",IF(A11<Calculator!$G$15,0,MIN(MIN(MOD(A11/Calculator!$F$15,1),1-MOD(A11/Calculator!$F$15,1)),ABS(MOD(A11/Calculator!$F$15,1)-0.5))),1) -> 0.053846154 | G11: =IF(Calculator!$E$16="YES",IF(A11<Calculator!$G$16,0,MIN(MIN(MOD(A11/Calculator!$F$16,1),1-MOD(A11/Calculator!$F$16,1)),ABS(MOD(A11/Calculator!$F$16,1)-0.5))),1) -> 0.22461538 | H11: =IF(Calculator!$E$17="YES",IF(A11<Calculator!$G$17,0,MIN(MIN(MOD(A11/Calculator!$F$17,1),1-MOD(A11/Calculator!$F$17,1)),ABS(MOD(A11/Calculator!$F$17,1)-0.5))),1) -> 0.0089299145 | I11: =IF(Calculator!$E$18="YES",IF(A11<Calculator!$G$18,0,MIN(MIN(MOD(A11/Calculator!$F$18,1),1-MOD(A11/Calculator!$F$18,1)),ABS(MOD(A11/Calculator!$F$18,1)-0.5))),1) -> 0.16102564 | J11: =IF(Calculator!$E$19="YES",IF(A11<Calculator!$G$19,0,MIN(MIN(MOD(A11/Calculator!$F$19,1),1-MOD(A11/Calculator!$F$19,1)),ABS(MOD(A11/Calculator!$F$19,1)-0.5))),1) -> 0.13576068 | K11: =IF(Calculator!$E$20="YES",IF(A11<Calculator!$G$20,0,MIN(MIN(MOD(A11/Calculator!$F$20,1),1-MOD(A11/Calculator!$F$20,1)),ABS(MOD(A11/Calculator!$F$20,1)-0.5))),1) -> 0.078119658 | L11: =IF(Calculator!$E$21="YES",IF(A11<Calculator!$G$21,0,MIN(MIN(MOD(A11/Calculator!$F$21,1),1-MOD(A11/Calculator!$F$21,1)),ABS(MOD(A11/Calculator!$F$21,1)-0.5))),1) -> 1 | M11: =MIN(B11:L11) -> 0.0089299145 | N11: =SUMPRODUCT(($M$5:$M$115>M11)*1)+SUMPRODUCT(($M$5:$M$115=M11)*(ROW($M$5:$M$115)<ROW(M11)))+1 -> 88 | O11: =IF(M11>=0.2,"★★★ EXCELLENT",IF(M11>=0.12,"★★ GOOD",IF(M11>=0.07,"★ FAIR",IF(M11>=0.025,"⚠ MARGINAL","✗ AVOID")))) -> ✗ AVOID
A12: 8.5 | B12: =IF(Calculator!$E$11="YES",IF(A12<Calculator!$G$11,0,MIN(MIN(MOD(A12/Calculator!$F$11,1),1-MOD(A12/Calculator!$F$11,1)),ABS(MOD(A12/Calculator!$F$11,1)-0.5))),1) -> 1 | C12: =IF(Calculator!$E$12="YES",IF(A12<Calculator!$G$12,0,MIN(MIN(MOD(A12/Calculator!$F$12,1),1-MOD(A12/Calculator!$F$12,1)),ABS(MOD(A12/Calculator!$F$12,1)-0.5))),1) -> 1 | D12: =IF(Calculator!$E$13="YES",IF(A12<Calculator!$G$13,0,MIN(MIN(MOD(A12/Calculator!$F$13,1),1-MOD(A12/Calculator!$F$13,1)),ABS(MOD(A12/Calculator!$F$13,1)-0.5))),1) -> 1 | E12: =IF(Calculator!$E$14="YES",IF(A12<Calculator!$G$14,0,MIN(MIN(MOD(A12/Calculator!$F$14,1),1-MOD(A12/Calculator!$F$14,1)),ABS(MOD(A12/Calculator!$F$14,1)-0.5))),1) -> 1 | F12: =IF(Calculator!$E$15="YES",IF(A12<Calculator!$G$15,0,MIN(MIN(MOD(A12/Calculator!$F$15,1),1-MOD(A12/Calculator!$F$15,1)),ABS(MOD(A12/Calculator!$F$15,1)-0.5))),1) -> 0.088461538 | G12: =IF(Calculator!$E$16="YES",IF(A12<Calculator!$G$16,0,MIN(MIN(MOD(A12/Calculator!$F$16,1),1-MOD(A12/Calculator!$F$16,1)),ABS(MOD(A12/Calculator!$F$16,1)-0.5))),1) -> 0.17615385 | H12: =IF(Calculator!$E$17="YES",IF(A12<Calculator!$G$17,0,MIN(MIN(MOD(A12/Calculator!$F$17,1),1-MOD(A12/Calculator!$F$17,1)),ABS(MOD(A12/Calculator!$F$17,1)-0.5))),1) -> 0.053011966 | I12: =IF(Calculator!$E$18="YES",IF(A12<Calculator!$G$18,0,MIN(MIN(MOD(A12/Calculator!$F$18,1),1-MOD(A12/Calculator!$F$18,1)),ABS(MOD(A12/Calculator!$F$18,1)-0.5))),1) -> 0.23358974 | J12: =IF(Calculator!$E$19="YES",IF(A12<Calculator!$G$19,0,MIN(MIN(MOD(A12/Calculator!$F$19,1),1-MOD(A12/Calculator!$F$19,1)),ABS(MOD(A12/Calculator!$F$19,1)-0.5))),1) -> 0.050495726 | K12: =IF(Calculator!$E$20="YES",IF(A12<Calculator!$G$20,0,MIN(MIN(MOD(A12/Calculator!$F$20,1),1-MOD(A12/Calculator!$F$20,1)),ABS(MOD(A12/Calculator!$F$20,1)-0.5))),1) -> 0.17675214 | L12: =IF(Calculator!$E$21="YES",IF(A12<Calculator!$G$21,0,MIN(MIN(MOD(A12/Calculator!$F$21,1),1-MOD(A12/Calculator!$F$21,1)),ABS(MOD(A12/Calculator!$F$21,1)-0.5))),1) -> 1 | M12: =MIN(B12:L12) -> 0.050495726 | N12: =SUMPRODUCT(($M$5:$M$115>M12)*1)+SUMPRODUCT(($M$5:$M$115=M12)*(ROW($M$5:$M$115)<ROW(M12)))+1 -> 31 | O12: =IF(M12>=0.2,"★★★ EXCELLENT",IF(M12>=0.12,"★★ GOOD",IF(M12>=0.07,"★ FAIR",IF(M12>=0.025,"⚠ MARGINAL","✗ AVOID")))) -> ⚠ MARGINAL
A13: 9 | B13: =IF(Calculator!$E$11="YES",IF(A13<Calculator!$G$11,0,MIN(MIN(MOD(A13/Calculator!$F$11,1),1-MOD(A13/Calculator!$F$11,1)),ABS(MOD(A13/Calculator!$F$11,1)-0.5))),1) -> 1 | C13: =IF(Calculator!$E$12="YES",IF(A13<Calculator!$G$12,0,MIN(MIN(MOD(A13/Calculator!$F$12,1),1-MOD(A13/Calculator!$F$12,1)),ABS(MOD(A13/Calculator!$F$12,1)-0.5))),1) -> 1 | D13: =IF(Calculator!$E$13="YES",IF(A13<Calculator!$G$13,0,MIN(MIN(MOD(A13/Calculator!$F$13,1),1-MOD(A13/Calculator!$F$13,1)),ABS(MOD(A13/Calculator!$F$13,1)-0.5))),1) -> 1 | E13: =IF(Calculator!$E$14="YES",IF(A13<Calculator!$G$14,0,MIN(MIN(MOD(A13/Calculator!$F$14,1),1-MOD(A13/Calculator!$F$14,1)),ABS(MOD(A13/Calculator!$F$14,1)-0.5))),1) -> 1 | F13: =IF(Calculator!$E$15="YES",IF(A13<Calculator!$G$15,0,MIN(MIN(MOD(A13/Calculator!$F$15,1),1-MOD(A13/Calculator!$F$15,1)),ABS(MOD(A13/Calculator!$F$15,1)-0.5))),1) -> 0.12307692 | G13: =IF(Calculator!$E$16="YES",IF(A13<Calculator!$G$16,0,MIN(MIN(MOD(A13/Calculator!$F$16,1),1-MOD(A13/Calculator!$F$16,1)),ABS(MOD(A13/Calculator!$F$16,1)-0.5))),1) -> 0.12769231 | H13: =IF(Calculator!$E$17="YES",IF(A13<Calculator!$G$17,0,MIN(MIN(MOD(A13/Calculator!$F$17,1),1-MOD(A13/Calculator!$F$17,1)),ABS(MOD(A13/Calculator!$F$17,1)-0.5))),1) -> 0.11495385 | I13: =IF(Calculator!$E$18="YES",IF(A13<Calculator!$G$18,0,MIN(MIN(MOD(A13/Calculator!$F$18,1),1-MOD(A13/Calculator!$F$18,1)),ABS(MOD(A13/Calculator!$F$18,1)-0.5))),1) -> 0.19384615 | J13: =IF(Calculator!$E$19="YES",IF(A13<Calculator!$G$19,0,MIN(MIN(MOD(A13/Calculator!$F$19,1),1-MOD(A13/Calculator!$F$19,1)),ABS(MOD(A13/Calculator!$F$19,1)-0.5))),1) -> 0.034769231 | K13: =IF(Calculator!$E$20="YES",IF(A13<Calculator!$G$20,0,MIN(MIN(MOD(A13/Calculator!$F$20,1),1-MOD(A13/Calculator!$F$20,1)),ABS(MOD(A13/Calculator!$F$20,1)-0.5))),1) -> 0.22461538 | L13: =IF(Calculator!$E$21="YES",IF(A13<Calculator!$G$21,0,MIN(MIN(MOD(A13/Calculator!$F$21,1),1-MOD(A13/Calculator!$F$21,1)),ABS(MOD(A13/Calculator!$F$21,1)-0.5))),1) -> 1 | M13: =MIN(B13:L13) -> 0.034769231 | N13: =SUMPRODUCT(($M$5:$M$115>M13)*1)+SUMPRODUCT(($M$5:$M$115=M13)*(ROW($M$5:$M$115)<ROW(M13)))+1 -> 46 | O13: =IF(M13>=0.2,"★★★ EXCELLENT",IF(M13>=0.12,"★★ GOOD",IF(M13>=0.07,"★ FAIR",IF(M13>=0.025,"⚠ MARGINAL","✗ AVOID")))) -> ⚠ MARGINAL
A14: 9.5 | B14: =IF(Calculator!$E$11="YES",IF(A14<Calculator!$G$11,0,MIN(MIN(MOD(A14/Calculator!$F$11,1),1-MOD(A14/Calculator!$F$11,1)),ABS(MOD(A14/Calculator!$F$11,1)-0.5))),1) -> 1 | C14: =IF(Calculator!$E$12="YES",IF(A14<Calculator!$G$12,0,MIN(MIN(MOD(A14/Calculator!$F$12,1),1-MOD(A14/Calculator!$F$12,1)),ABS(MOD(A14/Calculator!$F$12,1)-0.5))),1) -> 1 | D14: =IF(Calculator!$E$13="YES",IF(A14<Calculator!$G$13,0,MIN(MIN(MOD(A14/Calculator!$F$13,1),1-MOD(A14/Calculator!$F$13,1)),ABS(MOD(A14/Calculator!$F$13,1)-0.5))),1) -> 1 | E14: =IF(Calculator!$E$14="YES",IF(A14<Calculator!$G$14,0,MIN(MIN(MOD(A14/Calculator!$F$14,1),1-MOD(A14/Calculator!$F$14,1)),ABS(MOD(A14/Calculator!$F$14,1)-0.5))),1) -> 1 | F14: =IF(Calculator!$E$15="YES",IF(A14<Calculator!$G$15,0,MIN(MIN(MOD(A14/Calculator!$F$15,1),1-MOD(A14/Calculator!$F$15,1)),ABS(MOD(A14/Calculator!$F$15,1)-0.5))),1) -> 0.15769231 | G14: =IF(Calculator!$E$16="YES",IF(A14<Calculator!$G$16,0,MIN(MIN(MOD(A14/Calculator!$F$16,1),1-MOD(A14/Calculator!$F$16,1)),ABS(MOD(A14/Calculator!$F$16,1)-0.5))),1) -> 0.079230769 | H14: =IF(Calculator!$E$17="YES",IF(A14<Calculator!$G$17,0,MIN(MIN(MOD(A14/Calculator!$F$17,1),1-MOD(A14/Calculator!$F$17,1)),ABS(MOD(A14/Calculator!$F$17,1)-0.5))),1) -> 0.17689573 | I14: =IF(Calculator!$E$18="YES",IF(A14<Calculator!$G$18,0,MIN(MIN(MOD(A14/Calculator!$F$18,1),1-MOD(A14/Calculator!$F$18,1)),ABS(MOD(A14/Calculator!$F$18,1)-0.5))),1) -> 0.12128205 | J14: =IF(Calculator!$E$19="YES",IF(A14<Calculator!$G$19,0,MIN(MIN(MOD(A14/Calculator!$F$19,1),1-MOD(A14/Calculator!$F$19,1)),ABS(MOD(A14/Calculator!$F$19,1)-0.5))),1) -> 0.12003419 | K14: =IF(Calculator!$E$20="YES",IF(A14<Calculator!$G$20,0,MIN(MIN(MOD(A14/Calculator!$F$20,1),1-MOD(A14/Calculator!$F$20,1)),ABS(MOD(A14/Calculator!$F$20,1)-0.5))),1) -> 0.12598291 | L14: =IF(Calculator!$E$21="YES",IF(A14<Calculator!$G$21,0,MIN(MIN(MOD(A14/Calculator!$F$21,1),1-MOD(A14/Calculator!$F$21,1)),ABS(MOD(A14/Calculator!$F$21,1)-0.5))),1) -> 1 | M14: =MIN(B14:L14) -> 0.079230769 | N14: =SUMPRODUCT(($M$5:$M$115>M14)*1)+SUMPRODUCT(($M$5:$M$115=M14)*(ROW($M$5:$M$115)<ROW(M14)))+1 -> 12 | O14: =IF(M14>=0.2,"★★★ EXCELLENT",IF(M14>=0.12,"★★ GOOD",IF(M14>=0.07,"★ FAIR",IF(M14>=0.025,"⚠ MARGINAL","✗ AVOID")))) -> ★ FAIR
A15: 10 | B15: =IF(Calculator!$E$11="YES",IF(A15<Calculator!$G$11,0,MIN(MIN(MOD(A15/Calculator!$F$11,1),1-MOD(A15/Calculator!$F$11,1)),ABS(MOD(A15/Calculator!$F$11,1)-0.5))),1) -> 1 | C15: =IF(Calculator!$E$12="YES",IF(A15<Calculator!$G$12,0,MIN(MIN(MOD(A15/Calculator!$F$12,1),1-MOD(A15/Calculator!$F$12,1)),ABS(MOD(A15/Calculator!$F$12,1)-0.5))),1) -> 1 | D15: =IF(Calculator!$E$13="YES",IF(A15<Calculator!$G$13,0,MIN(MIN(MOD(A15/Calculator!$F$13,1),1-MOD(A15/Calculator!$F$13,1)),ABS(MOD(A15/Calculator!$F$13,1)-0.5))),1) -> 1 | E15: =IF(Calculator!$E$14="YES",IF(A15<Calculator!$G$14,0,MIN(MIN(MOD(A15/Calculator!$F$14,1),1-MOD(A15/Calculator!$F$14,1)),ABS(MOD(A15/Calculator!$F$14,1)-0.5))),1) -> 1 | F15: =IF(Calculator!$E$15="YES",IF(A15<Calculator!$G$15,0,MIN(MIN(MOD(A15/Calculator!$F$15,1),1-MOD(A15/Calculator!$F$15,1)),ABS(MOD(A15/Calculator!$F$15,1)-0.5))),1) -> 0.19230769 | G15: =IF(Calculator!$E$16="YES",IF(A15<Calculator!$G$16,0,MIN(MIN(MOD(A15/Calculator!$F$16,1),1-MOD(A15/Calculator!$F$16,1)),ABS(MOD(A15/Calculator!$F$16,1)-0.5))),1) -> 0.030769231 | H15: =IF(Calculator!$E$17="YES",IF(A15<Calculator!$G$17,0,MIN(MIN(MOD(A15/Calculator!$F$17,1),1-MOD(A15/Calculator!$F$17,1)),ABS(MOD(A15/Calculator!$F$17,1)-0.5))),1) -> 0.23883761 | I15: =IF(Calculator!$E$18="YES",IF(A15<Calculator!$G$18,0,MIN(MIN(MOD(A15/Calculator!$F$18,1),1-MOD(A15/Calculator!$F$18,1)),ABS(MOD(A15/Calculator!$F$18,1)-0.5))),1) -> 0.048717949 | J15: =IF(Calculator!$E$19="YES",IF(A15<Calculator!$G$19,0,MIN(MIN(MOD(A15/Calculator!$F$19,1),1-MOD(A15/Calculator!$F$19,1)),ABS(MOD(A15/Calculator!$F$19,1)-0.5))),1) -> 0.20529915 | K15: =IF(Calculator!$E$20="YES",IF(A15<Calculator!$G$20,0,MIN(MIN(MOD(A15/Calculator!$F$20,1),1-MOD(A15/Calculator!$F$20,1)),ABS(MOD(A15/Calculator!$F$20,1)-0.5))),1) -> 0.027350427 | L15: =IF(Calculator!$E$21="YES",IF(A15<Calculator!$G$21,0,MIN(MIN(MOD(A15/Calculator!$F$21,1),1-MOD(A15/Calculator!$F$21,1)),ABS(MOD(A15/Calculator!$F$21,1)-0.5))),1) -> 1 | M15: =MIN(B15:L15) -> 0.027350427 | N15: =SUMPRODUCT(($M$5:$M$115>M15)*1)+SUMPRODUCT(($M$5:$M$115=M15)*(ROW($M$5:$M$115)<ROW(M15)))+1 -> 56 | O15: =IF(M15>=0.2,"★★★ EXCELLENT",IF(M15>=0.12,"★★ GOOD",IF(M15>=0.07,"★ FAIR",IF(M15>=0.025,"⚠ MARGINAL","✗ AVOID")))) -> ⚠ MARGINAL
A16: 10.5 | B16: =IF(Calculator!$E$11="YES",IF(A16<Calculator!$G$11,0,MIN(MIN(MOD(A16/Calculator!$F$11,1),1-MOD(A16/Calculator!$F$11,1)),ABS(MOD(A16/Calculator!$F$11,1)-0.5))),1) -> 1 | C16: =IF(Calculator!$E$12="YES",IF(A16<Calculator!$G$12,0,MIN(MIN(MOD(A16/Calculator!$F$12,1),1-MOD(A16/Calculator!$F$12,1)),ABS(MOD(A16/Calculator!$F$12,1)-0.5))),1) -> 1 | D16: =IF(Calculator!$E$13="YES",IF(A16<Calculator!$G$13,0,MIN(MIN(MOD(A16/Calculator!$F$13,1),1-MOD(A16/Calculator!$F$13,1)),ABS(MOD(A16/Calculator!$F$13,1)-0.5))),1) -> 1 | E16: =IF(Calculator!$E$14="YES",IF(A16<Calculator!$G$14,0,MIN(MIN(MOD(A16/Calculator!$F$14,1),1-MOD(A16/Calculator!$F$14,1)),ABS(MOD(A16/Calculator!$F$14,1)-0.5))),1) -> 1 | F16: =IF(Calculator!$E$15="YES",IF(A16<Calculator!$G$15,0,MIN(MIN(MOD(A16/Calculator!$F$15,1),1-MOD(A16/Calculator!$F$15,1)),ABS(MOD(A16/Calculator!$F$15,1)-0.5))),1) -> 0.22692308 | G16: =IF(Calculator!$E$16="YES",IF(A16<Calculator!$G$16,0,MIN(MIN(MOD(A16/Calculator!$F$16,1),1-MOD(A16/Calculator!$F$16,1)),ABS(MOD(A16/Calculator!$F$16,1)-0.5))),1) -> 0.017692308 | H16: =IF(Calculator!$E$17="YES",IF(A16<Calculator!$G$17,0,MIN(MIN(MOD(A16/Calculator!$F$17,1),1-MOD(A16/Calculator!$F$17,1)),ABS(MOD(A16/Calculator!$F$17,1)-0.5))),1) -> 0.19922051 | I16: =IF(Calculator!$E$18="YES",IF(A16<Calculator!$G$18,0,MIN(MIN(MOD(A16/Calculator!$F$18,1),1-MOD(A16/Calculator!$F$18,1)),ABS(MOD(A16/Calculator!$F$18,1)-0.5))),1) -> 0.023846154 | J16: =IF(Calculator!$E$19="YES",IF(A16<Calculator!$G$19,0,MIN(MIN(MOD(A16/Calculator!$F$19,1),1-MOD(A16/Calculator!$F$19,1)),ABS(MOD(A16/Calculator!$F$19,1)-0.5))),1) -> 0.2094359 | K16: =IF(Calculator!$E$20="YES",IF(A16<Calculator!$G$20,0,MIN(MIN(MOD(A16/Calculator!$F$20,1),1-MOD(A16/Calculator!$F$20,1)),ABS(MOD(A16/Calculator!$F$20,1)-0.5))),1) -> 0.071282051 | L16: =IF(Calculator!$E$21="YES",IF(A16<Calculator!$G$21,0,MIN(MIN(MOD(A16/Calculator!$F$21,1),1-MOD(A16/Calculator!$F$21,1)),ABS(MOD(A16/Calculator!$F$21,1)-0.5))),1) -> 1 | M16: =MIN(B16:L16) -> 0.017692308 | N16: =SUMPRODUCT(($M$5:$M$115>M16)*1)+SUMPRODUCT(($M$5:$M$115=M16)*(ROW($M$5:$M$115)<ROW(M16)))+1 -> 73 | O16: =IF(M16>=0.2,"★★★ EXCELLENT",IF(M16>=0.12,"★★ GOOD",IF(M16>=0.07,"★ FAIR",IF(M16>=0.025,"⚠ MARGINAL","✗ AVOID")))) -> ✗ AVOID
... A115: 60 | B115: =IF(Calculator!$E$11="YES",IF(A115<Calculator!$G$11,0,MIN(MIN(MOD(A115/Calculator!$F$11,1),1-MOD(A115/Calculator!$F$11,1)),ABS(MOD(A115/Calculator!$F$11,1)-0.5))),1) -> 1 | C115: =IF(Calculator!$E$12="YES",IF(A115<Calculator!$G$12,0,MIN(MIN(MOD(A115/Calculator!$F$12,1),1-MOD(A115/Calculator!$F$12,1)),ABS(MOD(A115/Calculator!$F$12,1)-0.5))),1) -> 1 | D115: =IF(Calculator!$E$13="YES",IF(A115<Calculator!$G$13,0,MIN(MIN(MOD(A115/Calculator!$F$13,1),1-MOD(A115/Calculator!$F$13,1)),ABS(MOD(A115/Calculator!$F$13,1)-0.5))),1) -> 1 | E115: =IF(Calculator!$E$14="YES",IF(A115<Calculator!$G$14,0,MIN(MIN(MOD(A115/Calculator!$F$14,1),1-MOD(A115/Calculator!$F$14,1)),ABS(MOD(A115/Calculator!$F$14,1)-0.5))),1) -> 1 | F115: =IF(Calculator!$E$15="YES",IF(A115<Calculator!$G$15,0,MIN(MIN(MOD(A115/Calculator!$F$15,1),1-MOD(A115/Calculator!$F$15,1)),ABS(MOD(A115/Calculator!$F$15,1)-0.5))),1) -> 0.15384615 | G115: =IF(Calculator!$E$16="YES",IF(A115<Calculator!$G$16,0,MIN(MIN(MOD(A115/Calculator!$F$16,1),1-MOD(A115/Calculator!$F$16,1)),ABS(MOD(A115/Calculator!$F$16,1)-0.5))),1) -> 0.18461538 | H115: =IF(Calculator!$E$17="YES",IF(A115<Calculator!$G$17,0,MIN(MIN(MOD(A115/Calculator!$F$17,1),1-MOD(A115/Calculator!$F$17,1)),ABS(MOD(A115/Calculator!$F$17,1)-0.5))),1) -> 0.066974359 | I115: =IF(Calculator!$E$18="YES",IF(A115<Calculator!$G$18,0,MIN(MIN(MOD(A115/Calculator!$F$18,1),1-MOD(A115/Calculator!$F$18,1)),ABS(MOD(A115/Calculator!$F$18,1)-0.5))),1) -> 0.20769231 | J115: =IF(Calculator!$E$19="YES",IF(A115<Calculator!$G$19,0,MIN(MIN(MOD(A115/Calculator!$F$19,1),1-MOD(A115/Calculator!$F$19,1)),ABS(MOD(A115/Calculator!$F$19,1)-0.5))),1) -> 0.23179487 | K115: =IF(Calculator!$E$20="YES",IF(A115<Calculator!$G$20,0,MIN(MIN(MOD(A115/Calculator!$F$20,1),1-MOD(A115/Calculator!$F$20,1)),ABS(MOD(A115/Calculator!$F$20,1)-0.5))),1) -> 0.16410256 | L115: =IF(Calculator!$E$21="YES",IF(A115<Calculator!$G$21,0,MIN(MIN(MOD(A115/Calculator!$F$21,1),1-MOD(A115/Calculator!$F$21,1)),ABS(MOD(A115/Calculator!$F$21,1)-0.5))),1) -> 1 | M115: =MIN(B115:L115) -> 0.066974359 | N115: =SUMPRODUCT(($M$5:$M$115>M115)*1)+SUMPRODUCT(($M$5:$M$115=M115)*(ROW($M$5:$M$115)<ROW(M115)))+1 -> 17 | O115: =IF(M115>=0.2,"★★★ EXCELLENT",IF(M115>=0.12,"★★ GOOD",IF(M115>=0.07,"★ FAIR",IF(M115>=0.025,"⚠ MARGINAL","✗ AVOID")))) -> ⚠ MARGINAL

Sheet 9-1 UnUn Reference
A1: 📚 Technical Reference — Long Wire Antenna with 9:1 UnUn / Balun
A2: HOW THE 9:1 UnUn WORKS
A3: Parameter | B3: Value / Formula | C3: Example | D3: Notes
A4: Coax feedline impedance | B4: 50 Ω | C4: Standard RG-58/RG-213 | D4: Unbalanced
A5: Impedance transformation ratio | B5: 9 : 1 | C5: 50 × 9 = 450 Ω | D5: Turns ratio 1:3, impedance = 1:9
A6: Target wire feedpoint impedance | B6: ~450 Ω | C6: Varies 200–2000 Ω | D6: Aim for non-resonant wire
A7: Why called UnUn? | B7: Unbalanced-to-Unbalanced | C7: Both sides ground-referenced | D7: NOT a Balun (balanced–unbalanced)
A8: Core material | B8: FT-240-43 toroid (typical) | C8: 43-mix = 1–30 MHz | D8: FT-240-31 also used
A9: Winding (common) | B9: Primary: 8 turns / Secondary: 24 turns | C9: Ratio = 1:3 → Z ratio 1:9 | D9: Bifilar or trifilar winding
A10: Maximum recommended power (home build) | B10: 200–500 W PEP | C10: Depends on core & wire | D10: Commercial units to 1 kW+
A12: WIRE LENGTH SELECTION RULES
A13: Rule | B13: Explanation | C13: Good Example | D13: Bad Example | E13: Formula
A14: AVOID integer multiples of λ/2 | B14: Creates very high (>2000 Ω) or very low (<5 Ω) feedpoint impedance | C14: 20.3 m on 40m (not 1× λ/2 = 21.4 m) | D14: 21.4 m on 40m (exactly λ/2) | E14: Avoid: L = n × (VF × 150 / f)
A15: Aim for 3λ/8 points (mid-gap between λ/4 and λ/2) | B15: Gives moderate impedance the 9:1 UnUn can transform | C15: 15.3 m ≈ 3λ/8 at 7 MHz | D15: 21.4 m = λ/2 at 7 MHz (very high Z) | E15: L = n × (VF × 150 / f) ± (VF × 37.5 / f) [optimal: 3λ/8 or 5λ/8 points]
A16: Wire must be ≥ λ/4 at lowest band | B16: Below λ/4 the antenna becomes a very short radiator with high capacitive reactance | C16: 40 m band → min 10.7 m wire | D16: 5 m wire for 40m band | E16: L_min = VF × 75 / f_low
A17: Longer wire = better low-band performance | B17: More wire = more aperture for long wavelengths | C17: 37.8 m excellent for 80m+ | D17: 5.3 m struggles on 40m | E17: No upper limit, practical max ~60 m
A18: Classic 'random' lengths (air wire) | B18: Practical non-resonant lengths proven by hams | C18: 16.2 m, 20.1 m, 27.4 m, 37.8 m | D18: 21.0 m, 42.0 m (half-waves at 7 MHz) | E18: See Length Sweep sheet for calculated values
A20: AMATEUR RADIO HF BANDS QUICK REFERENCE
A21: Band | B21: f Low (MHz) | C21: f High (MHz) | D21: λ/2 @ center (m) | E21: Notes
A22: 160m | B22: 1.8 | C22: 2.0 | D22: 76.97 | E22: NVIS – skip fills in at night
A23: 80m | B23: 3.5 | C23: 3.8 | D23: 40.07 | E23: Best at night; regional/DX
A24: 60m | B24: 5.3515 | C24: 5.3665 | D24: 27.29 | E24: Fixed channels (ITU), limited use
A25: 40m | B25: 7.0 | C25: 7.3 | D25: 20.45 | E25: Day-regional, night-DX; most popular
A26: 30m | B26: 10.1 | C26: 10.15 | D26: 14.44 | E26: CW/digital only (WARC band)
A27: 20m | B27: 14.0 | C27: 14.35 | D27: 10.32 | E27: Best DX band worldwide
A28: 17m | B28: 18.068 | C28: 18.168 | D28: 8.07 | E28: WARC band; excellent DX
A29: 15m | B29: 21.0 | C29: 21.45 | D29: 6.89 | E29: Excellent DX when solar cycle high
A30: 12m | B30: 24.89 | C30: 24.99 | D30: 5.86 | E30: WARC band; similar to 10m
A31: 10m | B31: 28.0 | C31: 29.7 | D31: 5.07 | E31: Best when solar max; worldwide DX
A32: 6m | B32: 50.0 | C32: 54.0 | D32: 2.81 | E32: Magic band; sporadic-E openings
A34: COUNTERPOISE / GROUND SYSTEM
A35: Method | B35: Description | C35: Recommended Length | D35: Pros | E35: Cons
A36: Single counterpoise wire | B36: Wire from UnUn ground terminal | C36: λ/4 of lowest active band | D36: Simple, effective | E36: Band-specific length
A37: Multiple radials | B37: 2–4 wires at different angles | C37: λ/4 per target band | D37: Multi-band, improved efficiency | E37: More wire, more work
A38: RF earth ground | B38: Ground rod + clamp | C38: As short as possible to rod | D38: Simple at fixed station | E38: Variable effectiveness by soil
A39: Coax shield as counterpoise | B39: Leave outer shield connected to RF ground | C39: Long coax run helps | D39: No extra wire needed | E39: RFI in shack; need common-mode choke
A41: AVOIDANCE SCORE ALGORITHM (used in this calculator)
A42: Step | B42: Formula | C42: Value range | D42: Meaning
A43: 1 – Ratio | B43: R = Wire_Length / (VF × 150 / f_center) | C43: Any positive real | D43: How many half-waves fit in the wire
A44: 2 – Fractional part | B44: frac = MOD(R, 1) | C44: 0.0 to 1.0 | D44: 0 or 1.0 = on resonance
...
